Workbook

Sheet 2.4.1.1.
A1: Ümumi Daxili Məhsul (real artım tempi, deflyatoru, neft-qaz və qeyri neft-qaz sektorunun payı, onların real artım tempi və deflyatoru)
A2: № | B2: Göstəricilər | C2: Ölçü vahidi | D2: Hesabat | P2: Proqnoz
D3: =E3-1 -> 2013 | E3: =F3-1 -> 2014 | F3: =G3-1 -> 2015 | G3: =H3-1 -> 2016 | H3: =I3-1 -> 2017 | I3: =J3-1 -> 2018 | J3: =K3-1 -> 2019 | K3: =L3-1 -> 2020 | L3: =M3-1 -> 2021 | M3: 2022 | N3: 2023 | O3: 2024 | P3: 2025 | Q3: 2026 | R3: 2027 | S3: 2028 | T3: 2029 | U3: 2030
A4: 1. | B4: ÜDM bazar qiymətləri ilə | C4: mln AZN | D4: 58182 | E4: 59014.1 | F4: 54379.9 | G4: 60425.2 | H4: 70337.826 | I4: ='[1]ÜDM sahələr üzrə'!AC5 -> 80092 | J4: ='[1]ÜDM sahələr üzrə'!AD5 -> 81896.2 | K4: ='[1]ÜDM sahələr üzrə'!AE5 -> 72578.1 | L4: ='[1]ÜDM sahələr üzrə'!AF5 -> 93203.2 | M4: ='[1]ÜDM sahələr üzrə'!AG5 -> 133972.67 | N4: ='[1]ÜDM sahələr üzrə'!AH5 -> 123128.43 | O4: ='[1]ÜDM sahələr üzrə'!AI5 -> 126337.01 | P4: ='[1]ÜDM sahələr üzrə'!AJ5 -> 128134.21 | ... U4: ='[1]ÜDM sahələr üzrə'!AO5 -> 168392.95
B5: real artım tempi | C5: % | D5: 5.9072614 | E5: 2.8217374 | F5: 0.90314242 | G5: -3.1333177 | H5: 0.1760722 | I5: ='[1]ÜDM sahələr üzrə'!AC6 -> 1.5 | J5: ='[1]ÜDM sahələr üzrə'!AD6 -> 2.5 | K5: ='[1]ÜDM sahələr üzrə'!AE6 -> -4.2 | L5: ='[1]ÜDM sahələr üzrə'!AF6 -> 5.6 | M5: ='[1]ÜDM sahələr üzrə'!AG6 -> 4.6692037 | N5: ='[1]ÜDM sahələr üzrə'!AH6 -> 1.4193535 | O5: ='[1]ÜDM sahələr üzrə'!AI6 -> 4.0660314 | P5: ='[1]ÜDM sahələr üzrə'!AJ6 -> 3.1046397 | ... U5: ='[1]ÜDM sahələr üzrə'!AO6 -> 0.97038857
B6: deflyator | C6: % | D6: 0.2526305 | E6: -1.2533811 | F6: -8.6774721 | G6: 14.711053 | H6: 16.200192 | I6: ='[1]ÜDM sahələr üzrə'!AC7 -> 12.184877 | J6: ='[1]ÜDM sahələr üzrə'!AD7 -> -0.24130786 | K6: ='[1]ÜDM sahələr üzrə'!AE7 -> -7.4926298 | L6: ='[1]ÜDM sahələr üzrə'!AF7 -> 21.607766 | M6: ='[1]ÜDM sahələr üzrə'!AG7 -> 37.330337 | N6: ='[1]ÜDM sahələr üzrə'!AH7 -> -9.3805785 | O6: ='[1]ÜDM sahələr üzrə'!AI7 -> -1.4031027 | P6: ='[1]ÜDM sahələr üzrə'!AJ7 -> -1.6314423 | ... U6: ='[1]ÜDM sahələr üzrə'!AO7 -> 4.6446213
A7: 2. | B7: Neft-qaz sektoru, ÜDM, bazar qiymətləri ilə | C7: mln AZN | D7: 24968.4 | E7: 22824.9 | F7: 16459.6 | G7: 20449.38 | H7: 26026.04 | I7: ='[1]ÜDM sahələr üzrə'!AC366 -> 33389.4 | J7: ='[1]ÜDM sahələr üzrə'!AD366 -> 31246 | K7: ='[1]ÜDM sahələr üzrə'!AE366 -> 21446.64 | L7: ='[1]ÜDM sahələr üzrə'!AF366 -> 35770.8 | M7: ='[1]ÜDM sahələr üzrə'!AG366 -> 64208.55 | N7: ='[1]ÜDM sahələr üzrə'!AH366 -> 44138.1 | O7: ='[1]ÜDM sahələr üzrə'!AI366 -> 40624.6 | P7: ='[1]ÜDM sahələr üzrə'!AJ366 -> 36348.777 | ... U7: ='[1]ÜDM sahələr üzrə'!AO366 -> 32416.158
B8: real artım tempi | C8: % | D8: 1.0042109 | E8: -2.9295213 | F8: 1.1756349 | G8: -0.022276969 | H8: -5.0304021 | I8: ='[1]ÜDM sahələr üzrə'!AC367 -> 0.55870987 | J8: ='[1]ÜDM sahələr üzrə'!AD367 -> 0.43042648 | K8: ='[1]ÜDM sahələr üzrə'!AE367 -> -6.3352038 | L8: ='[1]ÜDM sahələr üzrə'!AF367 -> 2.021485 | M8: ='[1]ÜDM sahələr üzrə'!AG367 -> -2.4391456 | N8: ='[1]ÜDM sahələr üzrə'!AH367 -> -1.9643523 | O8: ='[1]ÜDM sahələr üzrə'!AI367 -> 0.25228338 | P8: ='[1]ÜDM sahələr üzrə'!AJ367 -> -0.19901236 | ... U8: ='[1]ÜDM sahələr üzrə'!AO367 -> -1.0913633
B9: deflyator | C9: % | D9: -2.988586 | E9: -5.926004 | F9: -28.725455 | G9: 24.267519 | H9: 34.011895 | I9: ='[1]ÜDM sahələr üzrə'!AC368 -> 27.579677 | J9: ='[1]ÜDM sahələr üzrə'!AD368 -> -6.8204719 | K9: ='[1]ÜDM sahələr üzrə'!AE368 -> -26.719497 | L9: ='[1]ÜDM sahələr üzrə'!AF368 -> 63.484939 | M9: ='[1]ÜDM sahələr üzrə'!AG368 -> 83.987625 | N9: ='[1]ÜDM sahələr üzrə'!AH368 -> -29.880833 | O9: ='[1]ÜDM sahələr üzrə'!AI368 -> -8.1918596 | P9: ='[1]ÜDM sahələr üzrə'!AJ368 -> -10.346785 | ... U9: ='[1]ÜDM sahələr üzrə'!AO368 -> 1.1990834
B10: payı (ÜDM-də) | C10: % | D10: 42.914303 | E10: 38.677028 | F10: 30.267801 | G10: 33.84247 | H10: 37.001485 | I10: =I7/I4*100 -> 41.688808 | J10: =J7/J4*100 -> 38.153174 | K10: =K7/K4*100 -> 29.54974 | L10: =L7/L4*100 -> 38.379369 | M10: =M7/M4*100 -> 47.926601 | N10: =N7/N4*100 -> 35.847204 | O10: =O7/O4*100 -> 32.15574 | P10: =P7/P4*100 -> 28.367738 | ... U10: =U7/U4*100 -> 19.250306
A11: 3. | B11: Qeyri neft-qaz sektoru, ÜDM, bazar qiymətləri ilə | C11: mln AZN | D11: 33213.651 | E11: 36189.121 | F11: 37920.535 | G11: 40008.562 | H11: 44311.786 | I11: ='[1]ÜDM sahələr üzrə'!AC363 -> 46702.58 | J11: ='[1]ÜDM sahələr üzrə'!AD363 -> 50650.2 | K11: ='[1]ÜDM sahələr üzrə'!AE363 -> 51131.45 | L11: ='[1]ÜDM sahələr üzrə'!AF363 -> 57432.43 | M11: ='[1]ÜDM sahələr üzrə'!AG363 -> 69764.125 | N11: ='[1]ÜDM sahələr üzrə'!AH363 -> 78990.333 | O11: ='[1]ÜDM sahələr üzrə'!AI363 -> 85712.41 | P11: ='[1]ÜDM sahələr üzrə'!AJ363 -> 91785.436 | ... U11: ='[1]ÜDM sahələr üzrə'!AO363 -> 135976.79
B12: real artım tempi | C12: % | D12: 10.176893 | E12: 6.9700734 | F12: 0.73128018 | G12: -4.4836613 | H12: 2.8370878 | I12: ='[1]ÜDM sahələr üzrə'!AC364 -> 1.9983642 | J12: ='[1]ÜDM sahələr üzrə'!AD364 -> 3.9551682 | K12: ='[1]ÜDM sahələr üzrə'!AE364 -> -2.9486197 | L12: ='[1]ÜDM sahələr üzrə'!AF364 -> 7.1321752 | M12: ='[1]ÜDM sahələr üzrə'!AG364 -> 9.0965142 | N12: ='[1]ÜDM sahələr üzrə'!AH364 -> 4.5336024 | O12: ='[1]ÜDM sahələr üzrə'!AI364 -> 6.1970718 | P12: ='[1]ÜDM sahələr üzrə'!AJ364 -> 4.670452 | ... U12: ='[1]ÜDM sahələr üzrə'!AO364 -> 1.4961981
B13: deflyator | C13: % | D13: 3.0200935 | E13: 1.9589337 | F13: 4.0236454 | G13: 10.458927 | H13: 7.7002087 | I13: ='[1]ÜDM sahələr üzrə'!AC365 -> 3.3304389 | J13: ='[1]ÜDM sahələr üzrə'!AD365 -> 4.3263963 | K13: ='[1]ÜDM sahələr üzrə'!AE365 -> 4.0172165 | L13: ='[1]ÜDM sahələr üzrə'!AF365 -> 4.8453468 | M13: ='[1]ÜDM sahələr üzrə'!AG365 -> 11.343299 | N13: ='[1]ÜDM sahələr üzrə'!AH365 -> 8.3143197 | O13: ='[1]ÜDM sahələr üzrə'!AI365 -> 2.177958 | P13: ='[1]ÜDM sahələr üzrə'!AJ365 -> 2.3071459 | ... U13: ='[1]ÜDM sahələr üzrə'!AO365 -> 5.5009362
B14: payı (ÜDM-də) | C14: % | D14: 57.085784 | E14: 61.322838 | F14: 69.732631 | G14: 66.211717 | H14: 62.998515 | I14: =I11/I4*100 -> 58.311167 | J14: =J11/J4*100 -> 61.846826 | K14: =K11/K4*100 -> 70.450246 | L14: =L11/L4*100 -> 61.620663 | M14: =M11/M4*100 -> 52.073399 | N14: =N11/N4*100 -> 64.152796 | O14: =O11/O4*100 -> 67.84426 | P14: =P11/P4*100 -> 71.632262 | ... U14: =U11/U4*100 -> 80.749694
B16: Əhali:
B17: İşğal olunmuş torpaqlar nəzərə alınmaqla (dövrün sonuna) | C17: min nəfər | D17: 9477.1 | E17: 9593 | F17: 9705.6 | G17: 9810 | H17: 9898.1 | I17: =[2]add9!AC5 -> 9951.4 | J17: =[2]add9!AD5 -> 9974 | K17: =[2]add9!AE5 -> 10026.1 | L17: =[2]add9!AF5 -> 10063.3 | M17: =[2]add9!AG5 -> 10127.145 | N17: =[2]add9!AH5 -> 10180.8 | O17: =[2]add9!AI5 -> 10224.9 | P17: =[2]add9!AJ5 -> 10269.4 | ... U17: =[2]add9!AO5 -> 10488.8
B18: İşğal olunmuş torpaqlar nəzərə alınmadan (orta illik) | C18: min nəfər | D18: 9296.8 | E18: 9415.05 | F18: 9529.3 | G18: 9637.8 | H18: 9734.05 | I18: =([2]add9!AC6+[2]add9!AB6)/2 -> 9804.75 | J18: =([2]add9!AD6+[2]add9!AC6)/2 -> 9902.7 | K18: =([2]add9!AE6+[2]add9!AD6)/2 -> 10000.05 | L18: =([2]add9!AF6+[2]add9!AE6)/2 -> 10044.7 | M18: =([2]add9!AG6+[2]add9!AF6)/2 -> 10095.222 | N18: =([2]add9!AH6+[2]add9!AG6)/2 -> 10153.972 | O18: =([2]add9!AI6+[2]add9!AH6)/2 -> 10202.85 | P18: =([2]add9!AJ6+[2]add9!AI6)/2 -> 10247.15 | ... U18: =([2]add9!AO6+[2]add9!AN6)/2 -> 10462.15
B19: Adambaşına düşən ÜDM-in həcmi:
B20: Manatla | C20: AZN | D20: =D4/D18*1000 -> 6258.2824 | E20: =E4/E18*1000 -> 6268.0602 | F20: =F4/F18*1000 -> 5706.5996 | G20: =G4/G18*1000 -> 6269.6051 | H20: =H4/H18*1000 -> 7225.957 | I20: =I4/I18*1000 -> 8168.6937 | J20: =J4/J18*1000 -> 8270.088 | K20: =K4/K18*1000 -> 7257.7737 | ... U20: =U4/U18*1000 -> 16095.444
B21: ABŞ dolları ilə | C21: USD | D21: =D20/D30 -> #REF! | E21: =E20/E30 -> #REF! | F21: =F20/F30 -> #REF! | G21: =G20/G30 -> #REF! | H21: =H20/H30 -> #REF! | I21: =I20/I30 -> #REF! | J21: =J20/J30 -> #REF! | K21: =K20/K30 -> #REF! | ... O21: =O20/O30 -> #REF! | P21: =P20/1.7 -> 7355.5151 | Q21: =Q20/1.7 -> 7433.7737 | R21: =R20/1.7 -> 7821.8627 | S21: =S20/1.7 -> 8316.1092 | T21: =T20/1.7 -> 9000.5123 | U21: =U20/1.7 -> 9467.908
B22: real artım tempi | C22: % | E22: =(1+E5/100)/(E18/D18)*100-100 -> 1.5303294 | F22: =(1+F5/100)/(F18/E18)*100-100 -> -0.30661948 | G22: =(1+G5/100)/(G18/F18)*100-100 -> -4.2238192 | H22: =(1+H5/100)/(H18/G18)*100-100 -> -0.81446585 | I22: =(1+I5/100)/(I18/H18)*100-100 -> 0.76810475 | J22: =(1+J5/100)/(J18/I18)*100-100 -> 1.4861477 | K22: =(1+K5/100)/(K18/J18)*100-100 -> -5.1326083 | L22: =(1+L5/100)/(L18/K18)*100-100 -> 5.1305942 | ... U22: =(1+U5/100)/(U18/T18)*100-100 -> 0.52402903
B23: Gəlirlər | C23: mln AZN | D23: ='2.4.1.5.-7.'!D30 -> 37562 | E23: ='2.4.1.5.-7.'!E30 -> 39472.2 | F23: ='2.4.1.5.-7.'!F30 -> 41744.8 | G23: ='2.4.1.5.-7.'!G30 -> 45395.1 | H23: ='2.4.1.5.-7.'!H30 -> 49187.9 | I23: ='2.4.1.5.-7.'!I30 -> 53103.7 | J23: ='2.4.1.5.-7.'!J30 -> 56769 | K23: ='2.4.1.5.-7.'!K30 -> 55754.1 | ... U23: ='2.4.1.5.-7.'!U30 -> 140165.6
B24: real artım tempi | C24: % | D24: ='2.4.1.5.-7.'!D31 -> 5.2923623 | E24: ='2.4.1.5.-7.'!E31 -> 3.7450757 | F24: ='2.4.1.5.-7.'!F31 -> 1.6808443 | G24: ='2.4.1.5.-7.'!G31 -> -3.2911345 | H24: ='2.4.1.5.-7.'!H31 -> -4.0568381 | I24: ='2.4.1.5.-7.'!I31 -> 5.5336275 | J24: ='2.4.1.5.-7.'!J31 -> 4.1931341 | K24: ='2.4.1.5.-7.'!K31 -> -4.425517 | ... U24: ='2.4.1.5.-7.'!U31 -> 1.6907043
B25: Xərclər | C25: mln AZN | D25: ='2.4.1.5.-7.'!D32 -> 28021.2 | E25: ='2.4.1.5.-7.'!E32 -> 30799.6 | F25: ='2.4.1.5.-7.'!F32 -> 34963.4 | G25: ='2.4.1.5.-7.'!G32 -> 39775 | H25: ='2.4.1.5.-7.'!H32 -> 44498.4 | I25: ='2.4.1.5.-7.'!I32 -> 47557.2 | J25: ='2.4.1.5.-7.'!J32 -> 51927.4 | K25: ='2.4.1.5.-7.'!K32 -> 49826.4 | ... U25: ='2.4.1.5.-7.'!U32 -> 134654.98
B26: real artım tempi | C26: % | D26: ='2.4.1.5.-7.'!D33 -> 9.7382306 | E26: ='2.4.1.5.-7.'!E33 -> 8.5087646 | F26: ='2.4.1.5.-7.'!F33 -> 9.1431978 | G26: ='2.4.1.5.-7.'!G33 -> 1.1710426 | H26: ='2.4.1.5.-7.'!H33 -> -0.93986168 | I26: ='2.4.1.5.-7.'!I33 -> 4.4711193 | J26: ='2.4.1.5.-7.'!J33 -> 6.4223734 | K26: ='2.4.1.5.-7.'!K33 -> -6.6231275 | ... U26: ='2.4.1.5.-7.'!U33 -> 1.3726534
B27: Neftin qiyməti | C27: USD/ barel | D27: ='2.4.1.5.-7.'!D4 -> 104.94 | E27: ='2.4.1.5.-7.'!E4 -> 94.76 | F27: ='2.4.1.5.-7.'!F4 -> 52.292257 | G27: ='2.4.1.5.-7.'!G4 -> 43.477243 | H27: ='2.4.1.5.-7.'!H4 -> 55.174566 | I27: ='2.4.1.5.-7.'!I4 -> 71.530797 | J27: ='2.4.1.5.-7.'!J4 -> 64.03 | K27: ='2.4.1.5.-7.'!K4 -> 42.3 | ... U27: ='2.4.1.5.-7.'!U4 -> 65
B28: İnflyasiya (İQİ, orta illik) | C28: % | D28: =#REF! -> #REF! | E28: =#REF! -> #REF! | F28: =#REF! -> #REF! | G28: =#REF! -> #REF! | H28: =#REF! -> #REF! | I28: =#REF! -> #REF! | J28: =#REF! -> #REF! | K28: =#REF! -> #REF! | ... O28: =#REF! -> #REF! | P28: ='2.4.1.5.-7.'!P54 -> 1.7422721 | Q28: ='2.4.1.5.-7.'!Q54 -> 2.7179719 | R28: ='2.4.1.5.-7.'!R54 -> 5.0653075 | S28: ='2.4.1.5.-7.'!S54 -> 6.7020945 | T28: ='2.4.1.5.-7.'!T54 -> 7.0662045 | U28: ='2.4.1.5.-7.'!U54 -> 7.2035648
B29: Valyuta məzənnəsi (orta illik):
B30: ABŞ dolları | C30: AZN/USD | D30: =#REF! -> #REF! | E30: =#REF! -> #REF! | F30: =#REF! -> #REF! | G30: =#REF! -> #REF! | H30: =#REF! -> #REF! | I30: =#REF! -> #REF! | J30: =#REF! -> #REF! | K30: =#REF! -> #REF! | ... R30: =#REF! -> #REF!
B31: Avro | C31: AZN/EUR | D31: =#REF! -> #REF! | E31: =#REF! -> #REF! | F31: =#REF! -> #REF! | G31: =#REF! -> #REF! | H31: =#REF! -> #REF! | I31: =#REF! -> #REF! | J31: =#REF! -> #REF! | K31: =#REF! -> #REF! | ... O31: =#REF! -> #REF!

Sheet 2.4.1.2.
A1: Ümumi Daxili Məhsulun istehsal strukturu (onların artım və deflyator indeksləri, ümumi buraxılışı, aralıq istehlakı, əlavə dəyəri)
A2: № | B2: Göstəricilər | C2: Ölçü vahidi | D2: Hesabat | P2: Proqnoz
D3: =E3-1 -> 2013 | E3: =F3-1 -> 2014 | F3: =G3-1 -> 2015 | G3: =H3-1 -> 2016 | H3: =I3-1 -> 2017 | I3: =J3-1 -> 2018 | J3: =K3-1 -> 2019 | K3: =L3-1 -> 2020 | L3: =M3-1 -> 2021 | M3: 2022 | N3: 2023 | O3: 2024 | P3: 2025 | Q3: 2026 | R3: 2027 | S3: 2028 | T3: 2029 | U3: 2030
A4: 1. | B4: Kənd, meşə və balıqçılıq təsərrüfatı
A5: a | B5: ümumi buraxılış | C5: mln AZN | D5: 5836.7 | E5: 5814.8 | F5: 6196.5 | G5: 6222.4 | H5: 7260.5 | I5: ='[1]ÜDM sahələr üzrə'!AC260 -> 7693.4 | J5: ='[1]ÜDM sahələr üzrə'!AD260 -> 8608.8 | K5: ='[1]ÜDM sahələr üzrə'!AE260 -> 9057.2 | L5: ='[1]ÜDM sahələr üzrə'!AF260 -> 9991.1 | M5: ='[1]ÜDM sahələr üzrə'!AG260 -> 11916.9 | N5: ='[1]ÜDM sahələr üzrə'!AH260 -> 13228.5 | O5: ='[1]ÜDM sahələr üzrə'!AI260 -> 13949.2 | P5: ='[1]ÜDM sahələr üzrə'!AJ260 -> 14692.736 | ... U5: ='[1]ÜDM sahələr üzrə'!AO260 -> 17857.038
A6: b | B6: aralıq istehlak | C6: mln AZN | D6: 2714.5 | E6: 2675.7 | F6: 2837.2 | G6: 2835.6 | H6: 3316.4 | I6: ='[1]ÜDM sahələr üzrə'!AC261 -> 3522.9 | J6: ='[1]ÜDM sahələr üzrə'!AD261 -> 3944.6 | K6: ='[1]ÜDM sahələr üzrə'!AE261 -> 4166.2 | L6: ='[1]ÜDM sahələr üzrə'!AF261 -> 4654.34 | M6: ='[1]ÜDM sahələr üzrə'!AG261 -> 5737.8 | N6: ='[1]ÜDM sahələr üzrə'!AH261 -> 6443.4 | O6: ='[1]ÜDM sahələr üzrə'!AI261 -> 6802.1 | P6: ='[1]ÜDM sahələr üzrə'!AJ261 -> 7164.6731 | ... U6: ='[1]ÜDM sahələr üzrə'!AO261 -> 8707.6935
A7: c | B7: əlavə dəyər | C7: mln AZN | D7: 3122.2 | E7: 3139.2 | F7: 3359.3 | G7: 3386.8 | H7: 3944.12 | I7: ='[1]ÜDM sahələr üzrə'!AC262 -> 4174.8 | J7: ='[1]ÜDM sahələr üzrə'!AD262 -> 4664.2 | K7: ='[1]ÜDM sahələr üzrə'!AE262 -> 4891 | L7: ='[1]ÜDM sahələr üzrə'!AF262 -> 5336.76 | M7: ='[1]ÜDM sahələr üzrə'!AG262 -> 6179.1 | N7: ='[1]ÜDM sahələr üzrə'!AH262 -> 6785.1 | O7: ='[1]ÜDM sahələr üzrə'!AI262 -> 7147.1 | P7: ='[1]ÜDM sahələr üzrə'!AJ262 -> 7528.0627 | ... U7: ='[1]ÜDM sahələr üzrə'!AO262 -> 9149.3445
B8: əlavə dəyərin xüsusi çəkisi | C8: % | D8: 53.492556 | E8: 53.98638 | F8: 54.212862 | G8: 54.429159 | H8: 54.322981 | I8: ='[1]ÜDM sahələr üzrə'!AC263 -> 54.264694 | J8: ='[1]ÜDM sahələr üzrə'!AD263 -> 54.179444 | K8: ='[1]ÜDM sahələr üzrə'!AE263 -> 54.001237 | L8: ='[1]ÜDM sahələr üzrə'!AF263 -> 53.415139 | M8: ='[1]ÜDM sahələr üzrə'!AG263 -> 51.851572 | N8: ='[1]ÜDM sahələr üzrə'!AH263 -> 51.29153 | O8: ='[1]ÜDM sahələr üzrə'!AI263 -> 51.23663 | P8: ='[1]ÜDM sahələr üzrə'!AJ263 -> 51.23663 | ... U8: ='[1]ÜDM sahələr üzrə'!AO263 -> 51.23663
B9: real artım tempi | C9: % | D9: 4.85 | E9: -2.6 | F9: 6.6 | G9: 2.6 | H9: 4.2 | I9: ='[1]ÜDM sahələr üzrə'!AC264 -> 4.6 | J9: ='[1]ÜDM sahələr üzrə'!AD264 -> 7.25 | K9: ='[1]ÜDM sahələr üzrə'!AE264 -> 1.949 | L9: ='[1]ÜDM sahələr üzrə'!AF264 -> 3.3 | M9: ='[1]ÜDM sahələr üzrə'!AG264 -> 3.4 | N9: ='[1]ÜDM sahələr üzrə'!AH264 -> 2.96 | O9: ='[1]ÜDM sahələr üzrə'!AI264 -> 1.4 | P9: ='[1]ÜDM sahələr üzrə'!AJ264 -> 2.3377665 | ... U9: ='[1]ÜDM sahələr üzrə'!AO264 -> 1.0872394
B10: deflyator | C10: % | D10: 5.8313885 | E10: 3.228427 | F10: 0.38587286 | G10: -1.736235 | H10: 11.761662 | I10: ='[1]ÜDM sahələr üzrə'!AC265 -> 1.1943051 | J10: ='[1]ÜDM sahələr üzrə'!AD265 -> 4.1703657 | K10: ='[1]ÜDM sahələr üzrə'!AE265 -> 2.8578703 | L10: ='[1]ÜDM sahələr üzrə'!AF265 -> 5.6281536 | M10: ='[1]ÜDM sahələr üzrə'!AG265 -> 11.976532 | N10: ='[1]ÜDM sahələr üzrə'!AH265 -> 6.6504016 | O10: ='[1]ÜDM sahələr üzrə'!AI265 -> 3.8808874 | P10: ='[1]ÜDM sahələr üzrə'!AJ265 -> 2.9241846 | ... U10: ='[1]ÜDM sahələr üzrə'!AO265 -> 1.7186532
A11: 2. | B11: Mədənçıxarma sənayesi
A12: a | B12: ümumi buraxılış | C12: mln AZN | D12: 24656.5 | E12: 21981 | F12: 16432.2 | G12: 21186.2 | H12: 28026 | I12: ='[1]ÜDM sahələr üzrə'!AC25 -> 34935 | J12: ='[1]ÜDM sahələr üzrə'!AD25 -> 32863.9 | K12: ='[1]ÜDM sahələr üzrə'!AE25 -> 22815 | L12: ='[1]ÜDM sahələr üzrə'!AF25 -> 36222.09 | M12: ='[1]ÜDM sahələr üzrə'!AG25 -> 64742.26 | N12: ='[1]ÜDM sahələr üzrə'!AH25 -> 45112.8 | O12: ='[1]ÜDM sahələr üzrə'!AI25 -> 41179.5 | P12: ='[1]ÜDM sahələr üzrə'!AJ25 -> 36430.199 | ... U12: ='[1]ÜDM sahələr üzrə'!AO25 -> 34261.72
A13: b | B13: aralıq istehlak | C13: mln AZN | D13: 1866.3 | E13: 1758.7 | F13: 2061.96 | G13: 2629.18 | H13: 3986.605 | I13: ='[1]ÜDM sahələr üzrə'!AC26 -> 3893.67 | J13: ='[1]ÜDM sahələr üzrə'!AD26 -> 4017.1 | K13: ='[1]ÜDM sahələr üzrə'!AE26 -> 3566.8 | L13: ='[1]ÜDM sahələr üzrə'!AF26 -> 3572.15 | M13: ='[1]ÜDM sahələr üzrə'!AG26 -> 4599.2 | N13: ='[1]ÜDM sahələr üzrə'!AH26 -> 4215.65 | O13: ='[1]ÜDM sahələr üzrə'!AI26 -> 4043.5 | P13: ='[1]ÜDM sahələr üzrə'!AJ26 -> 3922.9494 | ... U13: ='[1]ÜDM sahələr üzrə'!AO26 -> 5051.9808
A14: c | B14: əlavə dəyər | C14: mln AZN | D14: 22790.2 | E14: 20222.3 | F14: 14370.24 | G14: 18557.02 | H14: 24039.395 | I14: ='[1]ÜDM sahələr üzrə'!AC27 -> 31041.4 | J14: ='[1]ÜDM sahələr üzrə'!AD27 -> 28846.8 | K14: ='[1]ÜDM sahələr üzrə'!AE27 -> 19248.2 | L14: ='[1]ÜDM sahələr üzrə'!AF27 -> 32649.94 | M14: ='[1]ÜDM sahələr üzrə'!AG27 -> 60143.06 | N14: ='[1]ÜDM sahələr üzrə'!AH27 -> 40897.15 | O14: ='[1]ÜDM sahələr üzrə'!AI27 -> 37136 | P14: ='[1]ÜDM sahələr üzrə'!AJ27 -> 32507.25 | ... U14: ='[1]ÜDM sahələr üzrə'!AO27 -> 29209.739
B15: əlavə dəyərin xüsusi çəkisi | C15: % | D15: 92.430799 | E15: 91.998999 | F15: 87.451711 | G15: 87.590129 | H15: 85.775334 | I15: ='[1]ÜDM sahələr üzrə'!AC28 -> 88.85473 | J15: ='[1]ÜDM sahələr üzrə'!AD28 -> 87.776557 | K15: ='[1]ÜDM sahələr üzrə'!AE28 -> 84.366426 | L15: ='[1]ÜDM sahələr üzrə'!AF28 -> 90.1382 | M15: ='[1]ÜDM sahələr üzrə'!AG28 -> 92.896139 | N15: ='[1]ÜDM sahələr üzrə'!AH28 -> 90.655313 | O15: ='[1]ÜDM sahələr üzrə'!AI28 -> 90.180794 | P15: ='[1]ÜDM sahələr üzrə'!AJ28 -> 89.2316 | ... U15: ='[1]ÜDM sahələr üzrə'!AO28 -> 85.254737
B16: real artım tempi | C16: % | D16: 0.65307656 | E16: -2.7035704 | F16: 0.92485128 | G16: 0.74599213 | H16: -4.6299529 | I16: ='[1]ÜDM sahələr üzrə'!AC29 -> 0.36036077 | J16: ='[1]ÜDM sahələr üzrə'!AD29 -> 0.59694489 | K16: ='[1]ÜDM sahələr üzrə'!AE29 -> -6.6697786 | L16: ='[1]ÜDM sahələr üzrə'!AF29 -> 0.54720889 | M16: ='[1]ÜDM sahələr üzrə'!AG29 -> -2.3789937 | N16: ='[1]ÜDM sahələr üzrə'!AH29 -> -3.0764101 | O16: ='[1]ÜDM sahələr üzrə'!AI29 -> 0.81941832 | P16: ='[1]ÜDM sahələr üzrə'!AJ29 -> -0.37594767 | ... U16: ='[1]ÜDM sahələr üzrə'!AO29 -> -1.6208316
B17: deflyator | C17: % | D17: -4.0819106 | E17: -8.8019591 | F17: -29.589836 | G17: 28.178869 | H17: 35.832377 | I17: ='[1]ÜDM sahələr üzrə'!AC30 -> 28.66353 | J17: ='[1]ÜDM sahələr üzrə'!AD30 -> -7.6213626 | K17: ='[1]ÜDM sahələr üzrə'!AE30 -> -28.505903 | L17: ='[1]ÜDM sahələr üzrə'!AF30 -> 68.702782 | M17: ='[1]ÜDM sahələr üzrə'!AG30 -> 88.694766 | N17: ='[1]ÜDM sahələr üzrə'!AH30 -> -29.841866 | O17: ='[1]ÜDM sahələr üzrə'!AI30 -> -9.9346188 | P17: ='[1]ÜDM sahələr üzrə'!AJ30 -> -12.133991 | ... U17: ='[1]ÜDM sahələr üzrə'!AO30 -> 0.78378695
A18: 2.1. | B18: Xam neft və təbii qaz hasilatı
A19: a | B19: ümumi buraxılış | C19: mln AZN | D19: 23657.8 | E19: 20976.8 | F19: 14787.2 | G19: 18846.8 | H19: 24374.9 | I19: ='[1]ÜDM sahələr üzrə'!AC33 -> 31417.2 | J19: ='[1]ÜDM sahələr üzrə'!AD33 -> 29261.6 | K19: ='[1]ÜDM sahələr üzrə'!AE33 -> 19320.6 | L19: ='[1]ÜDM sahələr üzrə'!AF33 -> 33711.9 | M19: ='[1]ÜDM sahələr üzrə'!AG33 -> 62293.26 | N19: ='[1]ÜDM sahələr üzrə'!AH33 -> 42133.5 | O19: ='[1]ÜDM sahələr üzrə'!AI33 -> 38009.6 | P19: ='[1]ÜDM sahələr üzrə'!AJ33 -> 32631.383 | ... U19: ='[1]ÜDM sahələr üzrə'!AO33 -> 27258.694
A20: b | B20: aralıq istehlak | C20: mln AZN | D20: 1238.3 | E20: 1130 | F20: 1030.9 | G20: 1162.76 | H20: 1699.8 | I20: ='[1]ÜDM sahələr üzrə'!AC34 -> 1702.7 | J20: ='[1]ÜDM sahələr üzrə'!AD34 -> 1754.45 | K20: ='[1]ÜDM sahələr üzrə'!AE34 -> 1668.01 | L20: ='[1]ÜDM sahələr üzrə'!AF34 -> 2516.6 | M20: ='[1]ÜDM sahələr üzrə'!AG34 -> 3570.6 | N20: ='[1]ÜDM sahələr üzrə'!AH34 -> 3047.3 | O20: ='[1]ÜDM sahələr üzrə'!AI34 -> 2793.9 | P20: ='[1]ÜDM sahələr üzrə'!AJ34 -> 2398.5735 | ... U20: ='[1]ÜDM sahələr üzrə'!AO34 -> 2003.6534
A21: c | B21: əlavə dəyər | C21: mln AZN | D21: 22419.5 | E21: 19846.8 | F21: 13756.3 | G21: 17684.04 | H21: 22675.1 | I21: ='[1]ÜDM sahələr üzrə'!AC35 -> 29714.5 | J21: ='[1]ÜDM sahələr üzrə'!AD35 -> 27507.15 | K21: ='[1]ÜDM sahələr üzrə'!AE35 -> 17652.59 | L21: ='[1]ÜDM sahələr üzrə'!AF35 -> 31195.3 | M21: ='[1]ÜDM sahələr üzrə'!AG35 -> 58722.66 | N21: ='[1]ÜDM sahələr üzrə'!AH35 -> 39086.2 | O21: ='[1]ÜDM sahələr üzrə'!AI35 -> 35215.7 | P21: ='[1]ÜDM sahələr üzrə'!AJ35 -> 30232.809 | ... U21: ='[1]ÜDM sahələr üzrə'!AO35 -> 25255.04
B22: əlavə dəyərin xüsusi çəkisi | C22: % | D22: 94.765785 | E22: 94.613096 | F22: 93.02843 | G22: 93.830465 | H22: 93.026433 | I22: ='[1]ÜDM sahələr üzrə'!AC36 -> 94.580357 | J22: ='[1]ÜDM sahələr üzrə'!AD36 -> 94.004258 | K22: ='[1]ÜDM sahələr üzrə'!AE36 -> 91.366676 | L22: ='[1]ÜDM sahələr üzrə'!AF36 -> 92.53498 | M22: ='[1]ÜDM sahələr üzrə'!AG36 -> 94.26808 | N22: ='[1]ÜDM sahələr üzrə'!AH36 -> 92.767513 | O22: ='[1]ÜDM sahələr üzrə'!AI36 -> 92.649489 | P22: ='[1]ÜDM sahələr üzrə'!AJ36 -> 92.649489 | ... U22: ='[1]ÜDM sahələr üzrə'!AO36 -> 92.649489
B23: real artım tempi | C23: % | D23: 0.4770133 | E23: -2.8 | F23: -0.5 | G23: -0.2 | H23: -6.165 | I23: ='[1]ÜDM sahələr üzrə'!AC37 -> 1.07 | J23: ='[1]ÜDM sahələr üzrə'!AD37 -> 0.23 | K23: ='[1]ÜDM sahələr üzrə'!AE37 -> -6.1 | L23: ='[1]ÜDM sahələr üzrə'!AF37 -> 4.77 | M23: ='[1]ÜDM sahələr üzrə'!AG37 -> -1.783 | N23: ='[1]ÜDM sahələr üzrə'!AH37 -> -3.1 | O23: ='[1]ÜDM sahələr üzrə'!AI37 -> 1.095 | P23: ='[1]ÜDM sahələr üzrə'!AJ37 -> -1.0360244 | ... U23: ='[1]ÜDM sahələr üzrə'!AO37 -> -0.6842747
B24: deflyator | C24: % | D24: -3.8515971 | E24: -8.9251834 | F24: -30.339263 | G24: 28.80992 | H24: 36.647869 | I24: ='[1]ÜDM sahələr üzrə'!AC38 -> 29.657293 | J24: ='[1]ÜDM sahələr üzrə'!AD38 -> -7.640954 | K24: ='[1]ÜDM sahələr üzrə'!AE38 -> -31.656495 | L24: ='[1]ÜDM sahələr üzrə'!AF38 -> 68.672308 | M24: ='[1]ÜDM sahələr üzrə'!AG38 -> 91.659296 | N24: ='[1]ÜDM sahələr üzrə'!AH38 -> -31.309931 | O24: ='[1]ÜDM sahələr üzrə'!AI38 -> -10.878354 | P24: ='[1]ÜDM sahələr üzrə'!AJ38 -> -13.250886 | ... U24: ='[1]ÜDM sahələr üzrə'!AO38 -> 0.28505387
A25: 2.2. | B25: Metal filizlərinin hasilatı
A26: a | B26: ümumi buraxılış | C26: mln AZN | D26: 52.4 | E26: 55 | F26: 92.5 | G26: 127.9 | H26: 262.6 | I26: ='[1]ÜDM sahələr üzrə'!AC40 -> 248.4 | J26: ='[1]ÜDM sahələr üzrə'!AD40 -> 312.7 | K26: ='[1]ÜDM sahələr üzrə'!AE40 -> 390.4 | L26: ='[1]ÜDM sahələr üzrə'!AF40 -> 385.39 | M26: ='[1]ÜDM sahələr üzrə'!AG40 -> 361.4 | N26: ='[1]ÜDM sahələr üzrə'!AH40 -> 332.3 | O26: ='[1]ÜDM sahələr üzrə'!AI40 -> 382.4 | P26: ='[1]ÜDM sahələr üzrə'!AJ40 -> 637.19128 | ... U26: ='[1]ÜDM sahələr üzrə'!AO40 -> 2595.7405
A27: b | B27: aralıq istehlak | C27: mln AZN | D27: 35.2 | E27: 36.8 | F27: 61.6 | G27: 85.3 | H27: 175.16 | I27: ='[1]ÜDM sahələr üzrə'!AC41 -> 164.2 | J27: ='[1]ÜDM sahələr üzrə'!AD41 -> 206.99 | K27: ='[1]ÜDM sahələr üzrə'!AE41 -> 244.7 | L27: ='[1]ÜDM sahələr üzrə'!AF41 -> 189.49 | M27: ='[1]ÜDM sahələr üzrə'!AG41 -> 199 | N27: ='[1]ÜDM sahələr üzrə'!AH41 -> 173.5 | O27: ='[1]ÜDM sahələr üzrə'!AI41 -> 199.6 | P27: ='[1]ÜDM sahələr üzrə'!AJ41 -> 332.59252 | ... U27: ='[1]ÜDM sahələr üzrə'!AO41 -> 1354.8896
A28: c | B28: əlavə dəyər | C28: mln AZN | D28: 17.2 | E28: 18.2 | F28: 30.9 | G28: 42.6 | H28: 87.44 | I28: ='[1]ÜDM sahələr üzrə'!AC42 -> 84.2 | J28: ='[1]ÜDM sahələr üzrə'!AD42 -> 105.71 | K28: ='[1]ÜDM sahələr üzrə'!AE42 -> 145.7 | L28: ='[1]ÜDM sahələr üzrə'!AF42 -> 195.9 | M28: ='[1]ÜDM sahələr üzrə'!AG42 -> 162.4 | N28: ='[1]ÜDM sahələr üzrə'!AH42 -> 158.8 | O28: ='[1]ÜDM sahələr üzrə'!AI42 -> 182.8 | P28: ='[1]ÜDM sahələr üzrə'!AJ42 -> 304.59876 | ... U28: ='[1]ÜDM sahələr üzrə'!AO42 -> 1240.8508
B29: əlavə dəyərin xüsusi çəkisi | C29: % | D29: 32.824427 | E29: 33.090909 | F29: 33.405405 | G29: 33.307271 | H29: 33.297791 | I29: ='[1]ÜDM sahələr üzrə'!AC43 -> 33.89694 | J29: ='[1]ÜDM sahələr üzrə'!AD43 -> 33.805564 | K29: ='[1]ÜDM sahələr üzrə'!AE43 -> 37.320697 | L29: ='[1]ÜDM sahələr üzrə'!AF43 -> 50.831625 | M29: ='[1]ÜDM sahələr üzrə'!AG43 -> 44.936359 | N29: ='[1]ÜDM sahələr üzrə'!AH43 -> 47.788143 | O29: ='[1]ÜDM sahələr üzrə'!AI43 -> 47.803347 | P29: ='[1]ÜDM sahələr üzrə'!AJ43 -> 47.803347 | ... U29: ='[1]ÜDM sahələr üzrə'!AO43 -> 47.803347
B30: real artım tempi | C30: % | D30: -2.7 | E30: 16.1 | F30: 20.1 | G30: -11.58 | H30: 206.555 | I30: ='[1]ÜDM sahələr üzrə'!AC44 -> -32.78 | J30: ='[1]ÜDM sahələr üzrə'!AD44 -> 8.3 | K30: ='[1]ÜDM sahələr üzrə'!AE44 -> -5.22 | L30: ='[1]ÜDM sahələr üzrə'!AF44 -> -5.146 | M30: ='[1]ÜDM sahələr üzrə'!AG44 -> -3.8 | N30: ='[1]ÜDM sahələr üzrə'!AH44 -> -16.8 | O30: ='[1]ÜDM sahələr üzrə'!AI44 -> -11.2 | P30: ='[1]ÜDM sahələr üzrə'!AJ44 -> 70.693653 | ... U30: ='[1]ÜDM sahələr üzrə'!AO44 -> -11.3168
B31: deflyator | C31: % | D31: -69.730673 | E31: -9 | F31: 41.3 | G31: 55.919563 | H31: -33.043592 | I31: ='[1]ÜDM sahələr üzrə'!AC45 -> 43.252904 | J31: ='[1]ÜDM sahələr üzrə'!AD45 -> 15.924578 | K31: ='[1]ÜDM sahələr üzrə'!AE45 -> 45.420882 | L31: ='[1]ÜDM sahələr üzrə'!AF45 -> 41.748749 | M31: ='[1]ÜDM sahələr üzrə'!AG45 -> -13.825948 | N31: ='[1]ÜDM sahələr üzrə'!AH45 -> 17.527946 | O31: ='[1]ÜDM sahələr üzrə'!AI45 -> 29.632151 | P31: ='[1]ÜDM sahələr üzrə'!AJ45 -> -2.3809524 | ... U31: ='[1]ÜDM sahələr üzrə'!AO45 -> 0
A32: 2.3. | B32: Mədənçıxarma sənayesinin digər sahələri
A33: a | B33: ümumi buraxılış | C33: mln AZN | D33: 65.3 | E33: 49 | F33: 54.7 | G33: 37.7 | H33: 57.8 | I33: ='[1]ÜDM sahələr üzrə'!AC47 -> 60 | J33: ='[1]ÜDM sahələr üzrə'!AD47 -> 76.3 | K33: ='[1]ÜDM sahələr üzrə'!AE47 -> 81.5 | L33: ='[1]ÜDM sahələr üzrə'!AF47 -> 100 | M33: ='[1]ÜDM sahələr üzrə'!AG47 -> 180.3 | N33: ='[1]ÜDM sahələr üzrə'!AH47 -> 232.9 | O33: ='[1]ÜDM sahələr üzrə'!AI47 -> 256.7 | P33: ='[1]ÜDM sahələr üzrə'!AJ47 -> 295.37724 | ... U33: ='[1]ÜDM sahələr üzrə'!AO47 -> 569.89595
A34: b | B34: aralıq istehlak | C34: mln AZN | D34: 42.9 | E34: 32 | F34: 35.66 | G34: 24.62 | H34: 37.645 | I34: ='[1]ÜDM sahələr üzrə'!AC48 -> 39.02 | J34: ='[1]ÜDM sahələr üzrə'!AD48 -> 48.89 | K34: ='[1]ÜDM sahələr üzrə'!AE48 -> 49.18 | L34: ='[1]ÜDM sahələr üzrə'!AF48 -> 55.71 | M34: ='[1]ÜDM sahələr üzrə'!AG48 -> 98.16 | N34: ='[1]ÜDM sahələr üzrə'!AH48 -> 130.65 | O34: ='[1]ÜDM sahələr üzrə'!AI48 -> 144 | P34: ='[1]ÜDM sahələr üzrə'!AJ48 -> 165.69662 | ... U34: ='[1]ÜDM sahələr üzrə'!AO48 -> 319.69231
A35: c | B35: əlavə dəyər | C35: mln AZN | D35: 22.4 | E35: 17 | F35: 19.04 | G35: 13.08 | H35: 20.155 | I35: ='[1]ÜDM sahələr üzrə'!AC49 -> 20.98 | J35: ='[1]ÜDM sahələr üzrə'!AD49 -> 27.41 | K35: ='[1]ÜDM sahələr üzrə'!AE49 -> 32.32 | L35: ='[1]ÜDM sahələr üzrə'!AF49 -> 44.29 | M35: ='[1]ÜDM sahələr üzrə'!AG49 -> 82.14 | N35: ='[1]ÜDM sahələr üzrə'!AH49 -> 102.25 | O35: ='[1]ÜDM sahələr üzrə'!AI49 -> 112.7 | P35: ='[1]ÜDM sahələr üzrə'!AJ49 -> 129.68062 | ... U35: ='[1]ÜDM sahələr üzrə'!AO49 -> 250.20364
B36: əlavə dəyərin xüsusi çəkisi | C36: % | D36: 34.303216 | E36: 34.693878 | F36: 34.808044 | G36: 34.69496 | H36: 34.870242 | I36: ='[1]ÜDM sahələr üzrə'!AC50 -> 34.966667 | J36: ='[1]ÜDM sahələr üzrə'!AD50 -> 35.923984 | K36: ='[1]ÜDM sahələr üzrə'!AE50 -> 39.656442 | L36: ='[1]ÜDM sahələr üzrə'!AF50 -> 44.29 | M36: ='[1]ÜDM sahələr üzrə'!AG50 -> 45.557404 | N36: ='[1]ÜDM sahələr üzrə'!AH50 -> 43.902963 | O36: ='[1]ÜDM sahələr üzrə'!AI50 -> 43.903389 | P36: ='[1]ÜDM sahələr üzrə'!AJ50 -> 43.903389 | ... U36: ='[1]ÜDM sahələr üzrə'!AO50 -> 43.903389
B37: real artım tempi | C37: % | D37: -27.5 | E37: -0.5 | F37: 0.9 | G37: -8.3 | H37: 109.5 | I37: ='[1]ÜDM sahələr üzrə'!AC51 -> 66.6 | J37: ='[1]ÜDM sahələr üzrə'!AD51 -> 6.25 | K37: ='[1]ÜDM sahələr üzrə'!AE51 -> -10.35 | L37: ='[1]ÜDM sahələr üzrə'!AF51 -> 28.95 | M37: ='[1]ÜDM sahələr üzrə'!AG51 -> 12.55 | N37: ='[1]ÜDM sahələr üzrə'!AH51 -> -4.55 | O37: ='[1]ÜDM sahələr üzrə'!AI51 -> 35.7 | P37: ='[1]ÜDM sahələr üzrə'!AJ51 -> 13.096645 | ... U37: ='[1]ÜDM sahələr üzrə'!AO51 -> 7.8938796
B38: deflyator | C38: % | D38: 47.126437 | E38: -23.9 | F38: 11.3 | G38: -25.084538 | H38: -26.448585 | I38: ='[1]ÜDM sahələr üzrə'!AC52 -> -37.519041 | J38: ='[1]ÜDM sahələr üzrə'!AD52 -> 22.963046 | K38: ='[1]ÜDM sahələr üzrə'!AE52 -> 31.526124 | L38: ='[1]ÜDM sahələr üzrə'!AF52 -> 6.2705631 | M38: ='[1]ÜDM sahələr üzrə'!AG52 -> 64.779628 | N38: ='[1]ÜDM sahələr üzrə'!AH52 -> 30.416543 | O38: ='[1]ÜDM sahələr üzrə'!AI52 -> -18.776677 | P38: ='[1]ÜDM sahələr üzrə'!AJ52 -> 1.7422721 | ... U38: ='[1]ÜDM sahələr üzrə'!AO52 -> 7.2035648
A39: 2.4. | B39: Mədənçıxarma sənayesi sahəsinə xidmətlərin göstərilməsi
A40: a | B40: ümumi buraxılış | C40: mln AZN | D40: 881 | E40: 900.2 | F40: 1497.8 | G40: 2173.8 | H40: 3330.7 | I40: ='[1]ÜDM sahələr üzrə'!AC54 -> 3209.4 | J40: ='[1]ÜDM sahələr üzrə'!AD54 -> 3213.3 | K40: ='[1]ÜDM sahələr üzrə'!AE54 -> 3022.5 | L40: ='[1]ÜDM sahələr üzrə'!AF54 -> 2024.8 | M40: ='[1]ÜDM sahələr üzrə'!AG54 -> 1907.3 | N40: ='[1]ÜDM sahələr üzrə'!AH54 -> 2414.1 | O40: ='[1]ÜDM sahələr üzrə'!AI54 -> 2530.8 | P40: ='[1]ÜDM sahələr üzrə'!AJ54 -> 2866.2477 | ... U40: ='[1]ÜDM sahələr üzrə'!AO54 -> 3837.3896
...

Sheet 2.4.1.3.
A1: Ümumi Daxili Məhsulun sahə strukturu
A2: № | B2: Göstəricilər | C2: Ölçü vahidi | D2: Hesabat | P2: Proqnoz
D3: =E3-1 -> 2013 | E3: =F3-1 -> 2014 | F3: =G3-1 -> 2015 | G3: =H3-1 -> 2016 | H3: =I3-1 -> 2017 | I3: =J3-1 -> 2018 | J3: =K3-1 -> 2019 | K3: =L3-1 -> 2020 | L3: =M3-1 -> 2021 | M3: 2022 | N3: 2023 | O3: 2024 | P3: 2025 | Q3: 2026 | R3: 2027 | S3: 2028 | T3: 2029 | U3: 2030
A4: 1. | B4: Kənd, meşə və balıqçılıq təsərrüfatı | C4: ÜDM-də payı, % | D4: 5.3662645 | E4: 5.3194067 | F4: 6.1774663 | G4: 5.6049463 | H4: 5.6073953 | I4: =I5/'2.4.1.1.'!I$4*100 -> 5.2125056 | J4: =J5/'2.4.1.1.'!J$4*100 -> 5.6952581 | K4: =K5/'2.4.1.1.'!K$4*100 -> 6.7389474 | L4: =L5/'2.4.1.1.'!L$4*100 -> 5.7259407 | M4: =M5/'2.4.1.1.'!M$4*100 -> 4.6122092 | N4: =N5/'2.4.1.1.'!N$4*100 -> 5.5105875 | O4: =O5/'2.4.1.1.'!O$4*100 -> 5.6571705 | P4: =P5/'2.4.1.1.'!P$4*100 -> 5.8751387 | ... U4: =U5/'2.4.1.1.'!U$4*100 -> 5.43333
B5: əlavə dəyər | C5: mln AZN | D5: 3122.2 | E5: 3139.2 | F5: 3359.3 | G5: 3386.8 | H5: 3944.12 | I5: ='2.4.1.2.'!I7 -> 4174.8 | J5: ='2.4.1.2.'!J7 -> 4664.2 | K5: ='2.4.1.2.'!K7 -> 4891 | L5: ='2.4.1.2.'!L7 -> 5336.76 | M5: ='2.4.1.2.'!M7 -> 6179.1 | N5: ='2.4.1.2.'!N7 -> 6785.1 | O5: ='2.4.1.2.'!O7 -> 7147.1 | P5: ='2.4.1.2.'!P7 -> 7528.0627 | ... U5: ='2.4.1.2.'!U7 -> 9149.3445
B6: real artım tempi | C6: % | D6: 4.85 | E6: -2.6 | F6: 6.6 | G6: 2.6 | H6: 4.2 | I6: ='2.4.1.2.'!I9 -> 4.6 | J6: ='2.4.1.2.'!J9 -> 7.25 | K6: ='2.4.1.2.'!K9 -> 1.949 | L6: ='2.4.1.2.'!L9 -> 3.3 | M6: ='2.4.1.2.'!M9 -> 3.4 | N6: ='2.4.1.2.'!N9 -> 2.96 | O6: ='2.4.1.2.'!O9 -> 1.4 | P6: ='2.4.1.2.'!P9 -> 2.3377665 | ... U6: ='2.4.1.2.'!U9 -> 1.0872394
B7: deflyator | C7: % | D7: 5.8313885 | E7: 3.228427 | F7: 0.38587286 | G7: -1.736235 | H7: 11.761662 | I7: ='2.4.1.2.'!I10 -> 1.1943051 | J7: ='2.4.1.2.'!J10 -> 4.1703657 | K7: ='2.4.1.2.'!K10 -> 2.8578703 | L7: ='2.4.1.2.'!L10 -> 5.6281536 | M7: ='2.4.1.2.'!M10 -> 11.976532 | N7: ='2.4.1.2.'!N10 -> 6.6504016 | O7: ='2.4.1.2.'!O10 -> 3.8808874 | P7: ='2.4.1.2.'!P10 -> 2.9241846 | ... U7: ='2.4.1.2.'!U10 -> 1.7186532
A8: 2. | B8: Sənaye | C8: ÜDM-də payı, % | D8: 45.446445 | E8: 40.955163 | F8: 32.939625 | G8: 37.121436 | H8: 40.104205 | I8: =I9/'2.4.1.1.'!I$4*100 -> 44.530165 | J8: =J9/'2.4.1.1.'!J$4*100 -> 41.376645 | K8: =K9/'2.4.1.1.'!K$4*100 -> 34.077222 | L8: =L9/'2.4.1.1.'!L$4*100 -> 42.870481 | M8: =M9/'2.4.1.1.'!M$4*100 -> 51.303436 | N8: =N9/'2.4.1.1.'!N$4*100 -> 39.641317 | O8: =O9/'2.4.1.1.'!O$4*100 -> 35.901285 | P8: =P9/'2.4.1.1.'!P$4*100 -> 32.787059 | ... U8: =U9/'2.4.1.1.'!U$4*100 -> 25.521463
B9: əlavə dəyər | C9: mln AZN | D9: 26441.651 | E9: 24169.121 | F9: 17912.535 | G9: 22430.702 | H9: 28208.426 | I9: ='[1]ÜDM sahələr üzrə'!AC12 -> 35665.1 | J9: ='[1]ÜDM sahələr üzrə'!AD12 -> 33885.9 | K9: ='[1]ÜDM sahələr üzrə'!AE12 -> 24732.6 | L9: ='[1]ÜDM sahələr üzrə'!AF12 -> 39956.66 | M9: ='[1]ÜDM sahələr üzrə'!AG12 -> 68732.585 | N9: ='[1]ÜDM sahələr üzrə'!AH12 -> 48809.733 | O9: ='[1]ÜDM sahələr üzrə'!AI12 -> 45356.61 | P9: ='[1]ÜDM sahələr üzrə'!AJ12 -> 42011.44 | ... U9: ='[1]ÜDM sahələr üzrə'!AO12 -> 42976.343
B10: real artım tempi | C10: % | D10: 1.1353519 | E10: -1.6997543 | F10: 1.5821082 | G10: 0.38572825 | H10: -4.0699059 | I10: ='[1]ÜDM sahələr üzrə'!AC14 -> 1.2571434 | J10: ='[1]ÜDM sahələr üzrə'!AD14 -> 1.6985953 | K10: ='[1]ÜDM sahələr üzrə'!AE14 -> -4.5215475 | L10: ='[1]ÜDM sahələr üzrə'!AF14 -> 4.2815779 | M10: ='[1]ÜDM sahələr üzrə'!AG14 -> -1.376918 | N10: ='[1]ÜDM sahələr üzrə'!AH14 -> -1.6960598 | O10: ='[1]ÜDM sahələr üzrə'!AI14 -> 0.94674976 | P10: ='[1]ÜDM sahələr üzrə'!AJ14 -> 1.1095726 | ... U10: ='[1]ÜDM sahələr üzrə'!AO14 -> -0.39202719
B11: deflyator | C11: % | D11: -3.4288446 | E11: -7.0139741 | F11: -26.040983 | G11: 24.742327 | H11: 31.093488 | I11: ='[1]ÜDM sahələr üzrə'!AC15 -> 24.864155 | J11: ='[1]ÜDM sahələr üzrə'!AD15 -> -6.5755339 | K11: ='[1]ÜDM sahələr üzrə'!AE15 -> -23.555653 | L11: ='[1]ÜDM sahələr üzrə'!AF15 -> 54.921542 | M11: ='[1]ÜDM sahələr üzrə'!AG15 -> 74.419457 | N11: ='[1]ÜDM sahələr üzrə'!AH15 -> -27.660817 | O11: ='[1]ÜDM sahələr üzrə'!AI15 -> -7.9461802 | P11: ='[1]ÜDM sahələr üzrə'!AJ15 -> -8.3917253 | ... U11: ='[1]ÜDM sahələr üzrə'!AO15 -> 1.5378257
A12: 2.1. | B12: Neft və qaz sənayesi | C12: ÜDM-də payı, % | D12: 40.868482 | E12: 36.271332 | F12: 28.286554 | G12: 32.35842 | H12: 35.550487 | I12: =I13/'2.4.1.1.'!I$4*100 -> 40.243345 | J12: =J13/'2.4.1.1.'!J$4*100 -> 36.695109 | K12: =K13/'2.4.1.1.'!K$4*100 -> 28.131764 | L12: =L13/'2.4.1.1.'!L$4*100 -> 37.017399 | M12: =M13/'2.4.1.1.'!M$4*100 -> 46.644228 | N12: =N13/'2.4.1.1.'!N$4*100 -> 34.334799 | O12: =O13/'2.4.1.1.'!O$4*100 -> 30.583358 | P12: =P13/'2.4.1.1.'!P$4*100 -> 26.980585 | ... U12: =U13/'2.4.1.1.'!U$4*100 -> 18.308987
B13: əlavə dəyər | C13: mln AZN | D13: 23778.1 | E13: 21405.2 | F13: 15382.2 | G13: 19552.64 | H13: 25005.44 | I13: ='[1]ÜDM sahələr üzrə'!AC71 -> 32231.7 | J13: ='[1]ÜDM sahələr üzrə'!AD71 -> 30051.9 | K13: ='[1]ÜDM sahələr üzrə'!AE71 -> 20417.5 | L13: ='[1]ÜDM sahələr üzrə'!AF71 -> 34501.4 | M13: ='[1]ÜDM sahələr üzrə'!AG71 -> 62490.52 | N13: ='[1]ÜDM sahələr üzrə'!AH71 -> 42275.9 | O13: ='[1]ÜDM sahələr üzrə'!AI71 -> 38638.1 | P13: ='[1]ÜDM sahələr üzrə'!AJ71 -> 34571.361 | ... U13: ='[1]ÜDM sahələr üzrə'!AO71 -> 30831.042
B14: real artım tempi | C14: % | D14: 0.90285985 | E14: -2.8656196 | F14: 0.57709388 | G14: 0.1022383 | H14: -5.3363259 | I14: ='[1]ÜDM sahələr üzrə'!AC73 -> 0.53620886 | J14: ='[1]ÜDM sahələr üzrə'!AD73 -> 0.42074393 | K14: ='[1]ÜDM sahələr üzrə'!AE73 -> -6.5034879 | L14: ='[1]ÜDM sahələr üzrə'!AF73 -> 1.3975484 | M14: ='[1]ÜDM sahələr üzrə'!AG73 -> -2.4821616 | N14: ='[1]ÜDM sahələr üzrə'!AH73 -> -2.5022282 | O14: ='[1]ÜDM sahələr üzrə'!AI73 -> 0.32330243 | P14: ='[1]ÜDM sahələr üzrə'!AJ73 -> -0.19901236 | ... U14: ='[1]ÜDM sahələr üzrə'!AO73 -> -1.0913633
B15: deflyator | C15: % | D15: -3.7650618 | E15: -7.3235976 | F15: -28.450354 | G15: 26.982292 | H15: 35.097011 | I15: ='[1]ÜDM sahələr üzrə'!AC74 -> 28.211477 | J15: ='[1]ÜDM sahələr üzrə'!AD74 -> -7.1535531 | K15: ='[1]ÜDM sahələr üzrə'!AE74 -> -27.333337 | L15: ='[1]ÜDM sahələr üzrə'!AF74 -> 66.65053 | M15: ='[1]ÜDM sahələr üzrə'!AG74 -> 85.734831 | N15: ='[1]ÜDM sahələr üzrə'!AH74 -> -30.612054 | O15: ='[1]ÜDM sahələr üzrə'!AI74 -> -8.8994329 | P15: ='[1]ÜDM sahələr üzrə'!AJ74 -> -10.346785 | ... U15: ='[1]ÜDM sahələr üzrə'!AO74 -> 1.1990834
A16: 2.2. | B16: Qeyri neft-qaz sənayesi | C16: ÜDM-də payı, % | D16: 4.5779636 | E16: 4.6838315 | F16: 4.6530705 | G16: 4.7630163 | H16: 4.5537181 | I16: =I17/'2.4.1.1.'!I$4*100 -> 4.2867452 | J16: =J17/'2.4.1.1.'!J$4*100 -> 4.6815115 | K16: =K17/'2.4.1.1.'!K$4*100 -> 5.9454849 | L16: =L17/'2.4.1.1.'!L$4*100 -> 5.8529106 | M16: =M17/'2.4.1.1.'!M$4*100 -> 4.6592076 | N16: =N17/'2.4.1.1.'!N$4*100 -> 5.3065184 | O16: =O17/'2.4.1.1.'!O$4*100 -> 5.317927 | P16: =P17/'2.4.1.1.'!P$4*100 -> 5.8064735 | ... U16: =U17/'2.4.1.1.'!U$4*100 -> 7.2124762
B17: əlavə dəyər | C17: mln AZN | D17: 2663.5508 | E17: 2763.921 | F17: 2530.3351 | G17: 2878.0621 | H17: 3202.9863 | I17: ='[1]ÜDM sahələr üzrə'!AC20 -> 3433.34 | J17: ='[1]ÜDM sahələr üzrə'!AD20 -> 3833.98 | K17: ='[1]ÜDM sahələr üzrə'!AE20 -> 4315.12 | L17: ='[1]ÜDM sahələr üzrə'!AF20 -> 5455.1 | M17: ='[1]ÜDM sahələr üzrə'!AG20 -> 6242.065 | N17: ='[1]ÜDM sahələr üzrə'!AH20 -> 6533.833 | O17: ='[1]ÜDM sahələr üzrə'!AI20 -> 6718.5099 | P17: ='[1]ÜDM sahələr üzrə'!AJ20 -> 7440.0792 | ... U17: ='[1]ÜDM sahələr üzrə'!AO20 -> 12145.301
B18: real artım tempi | C18: % | D18: 3.4370233 | E18: 8.7081805 | F18: 5.8 | G18: 2.1090965 | H18: 4.5337489 | I18: ='[1]ÜDM sahələr üzrə'!AC22 -> 6.885376 | J18: ='[1]ÜDM sahələr üzrə'!AD22 -> 13.696948 | K18: ='[1]ÜDM sahələr üzrə'!AE22 -> 11.014783 | L18: ='[1]ÜDM sahələr üzrə'!AF22 -> 17.927453 | M18: ='[1]ÜDM sahələr üzrə'!AG22 -> 5.6141965 | N18: ='[1]ÜDM sahələr üzrə'!AH22 -> 6.3746479 | O18: ='[1]ÜDM sahələr üzrə'!AI22 -> 4.9806449 | P18: ='[1]ÜDM sahələr üzrə'!AJ22 -> 8.635235 | ... U18: ='[1]ÜDM sahələr üzrə'!AO22 -> 1.4506263
B19: deflyator | C19: % | D19: -0.41627677 | E19: -4.5441796 | F19: -1.8 | G19: 11.392947 | H19: 6.4629249 | I19: ='[1]ÜDM sahələr üzrə'!AC23 -> 0.28332026 | J19: ='[1]ÜDM sahələr üzrə'!AD23 -> -1.7835522 | K19: ='[1]ÜDM sahələr üzrə'!AE23 -> 1.3823184 | L19: ='[1]ÜDM sahələr üzrə'!AF23 -> 7.2000336 | M19: ='[1]ÜDM sahələr üzrə'!AG23 -> 8.3436022 | N19: ='[1]ÜDM sahələr üzrə'!AH23 -> -1.5985251 | O19: ='[1]ÜDM sahələr üzrə'!AI23 -> -2.0519724 | P19: ='[1]ÜDM sahələr üzrə'!AJ23 -> 1.937479 | ... U19: ='[1]ÜDM sahələr üzrə'!AO23 -> 2.4080007
A20: 3. | B20: Tikinti | C20: ÜDM-də payı, % | D20: 11.607886 | E20: 12.631558 | F20: 11.952026 | G20: 10.490491 | H20: 9.5974248 | I20: =I21/'2.4.1.1.'!I$4*100 -> 7.7203716 | J20: =J21/'2.4.1.1.'!J$4*100 -> 7.4469878 | K20: =K21/'2.4.1.1.'!K$4*100 -> 7.8790985 | L20: =L21/'2.4.1.1.'!L$4*100 -> 5.9476391 | M20: =M21/'2.4.1.1.'!M$4*100 -> 4.8433011 | N20: =N21/'2.4.1.1.'!N$4*100 -> 6.1995429 | O20: =O21/'2.4.1.1.'!O$4*100 -> 6.7107018 | P20: =P21/'2.4.1.1.'!P$4*100 -> 7.1247375 | ... U20: =U21/'2.4.1.1.'!U$4*100 -> 6.7096002
B21: əlavə dəyər | C21: mln AZN | D21: 6753.7 | E21: 7454.4 | F21: 6499.5 | G21: 6338.9 | H21: 6750.62 | I21: ='[1]ÜDM sahələr üzrə'!AC271 -> 6183.4 | J21: ='[1]ÜDM sahələr üzrə'!AD271 -> 6098.8 | K21: ='[1]ÜDM sahələr üzrə'!AE271 -> 5718.5 | L21: ='[1]ÜDM sahələr üzrə'!AF271 -> 5543.39 | M21: ='[1]ÜDM sahələr üzrə'!AG271 -> 6488.7 | N21: ='[1]ÜDM sahələr üzrə'!AH271 -> 7633.4 | O21: ='[1]ÜDM sahələr üzrə'!AI271 -> 8478.1 | P21: ='[1]ÜDM sahələr üzrə'!AJ271 -> 9129.2263 | ... U21: ='[1]ÜDM sahələr üzrə'!AO271 -> 11298.493
B22: real artım tempi | C22: % | D22: 21.25 | E22: 8.8 | F22: -13.4 | G22: -22.6 | H22: 0.2 | I22: ='[1]ÜDM sahələr üzrə'!AC273 -> -8.8 | J22: ='[1]ÜDM sahələr üzrə'!AD273 -> -2.8 | K22: ='[1]ÜDM sahələr üzrə'!AE273 -> -7.7 | L22: ='[1]ÜDM sahələr üzrə'!AF273 -> -1.636 | M22: ='[1]ÜDM sahələr üzrə'!AG273 -> 13.2 | N22: ='[1]ÜDM sahələr üzrə'!AH273 -> 14.6 | O22: ='[1]ÜDM sahələr üzrə'!AI273 -> 9.6 | P22: ='[1]ÜDM sahələr üzrə'!AJ273 -> 5.8321599 | ... U22: ='[1]ÜDM sahələr üzrə'!AO273 -> -6.8641012
B23: deflyator | C23: % | D23: 1.1285945 | E23: 1.4476596 | F23: 0.68142714 | G23: 26.006513 | H23: 6.2825681 | I23: ='[1]ÜDM sahələr üzrə'!AC276 -> 0.43616656 | J23: ='[1]ÜDM sahələr üzrə'!AD276 -> 1.4730665 | K23: ='[1]ÜDM sahələr üzrə'!AE276 -> 1.5865082 | L23: ='[1]ÜDM sahələr üzrə'!AF276 -> -1.4498868 | M23: ='[1]ÜDM sahələr üzrə'!AG276 -> 3.4036418 | N23: ='[1]ÜDM sahələr üzrə'!AH276 -> 2.65396 | O23: ='[1]ÜDM sahələr üzrə'!AI276 -> 1.3374473 | P23: ='[1]ÜDM sahələr üzrə'!AJ276 -> 1.7461016 | ... U23: ='[1]ÜDM sahələr üzrə'!AO276 -> 3.8725136
A24: 4. | B24: Xidmətlərin istehsalı | C24: ÜDM-də payı, % | D24: 30.913769 | E24: 33.615999 | F24: 39.995596 | G24: 38.638346 | H24: 37.576109 | I24: =I25/'2.4.1.1.'!I$4*100 -> 34.797982 | J24: =J25/'2.4.1.1.'!J$4*100 -> 36.49107 | K24: =K25/'2.4.1.1.'!K$4*100 -> 41.868828 | L24: =L25/'2.4.1.1.'!L$4*100 -> 37.323686 | M24: =M25/'2.4.1.1.'!M$4*100 -> 31.796932 | N24: =N25/'2.4.1.1.'!N$4*100 -> 39.414536 | O24: =O25/'2.4.1.1.'!O$4*100 -> 41.945033 | P24: =P25/'2.4.1.1.'!P$4*100 -> 44.207407 | ... U24: =U25/'2.4.1.1.'!U$4*100 -> 52.236715
B25: əlavə dəyər | C25: mln AZN | D25: 17986.249 | E25: 19838.379 | F25: 21749.565 | G25: 23347.298 | H25: 26430.218 | I25: ='[1]ÜDM sahələr üzrə'!AC282 -> 27870.4 | J25: ='[1]ÜDM sahələr üzrə'!AD282 -> 29884.8 | K25: ='[1]ÜDM sahələr üzrə'!AE282 -> 30387.6 | L25: ='[1]ÜDM sahələr üzrə'!AF282 -> 34786.87 | M25: ='[1]ÜDM sahələr üzrə'!AG282 -> 42599.2 | N25: ='[1]ÜDM sahələr üzrə'!AH282 -> 48530.5 | O25: ='[1]ÜDM sahələr üzrə'!AI282 -> 52992.1 | P25: ='[1]ÜDM sahələr üzrə'!AJ282 -> 56644.814 | ... U25: ='[1]ÜDM sahələr üzrə'!AO282 -> 87962.943
B26: real artım tempi | C26: % | D26: 8.3539137 | E26: 7.547302 | F26: 4.4395771 | G26: -0.8065074 | H26: 3.1565799 | I26: ='[1]ÜDM sahələr üzrə'!AC284 -> 3.8080658 | J26: ='[1]ÜDM sahələr üzrə'!AD284 -> 3.8064167 | K26: ='[1]ÜDM sahələr üzrə'!AE284 -> -4.447776 | L26: ='[1]ÜDM sahələr üzrə'!AF284 -> 7.7764685 | M26: ='[1]ÜDM sahələr üzrə'!AG284 -> 9.7640449 | N26: ='[1]ÜDM sahələr üzrə'!AH284 -> 2.9265314 | O26: ='[1]ÜDM sahələr üzrə'!AI284 -> 6.4173413 | P26: ='[1]ÜDM sahələr üzrə'!AJ284 -> 4.2965363 | ... U26: ='[1]ÜDM sahələr üzrə'!AO284 -> 2.7671018
B27: deflyator | C27: % | D27: 4.0267501 | E27: 2.5571768 | F27: 4.9734052 | G27: 8.2188386 | H27: 9.7405636 | I27: ='[1]ÜDM sahələr üzrə'!AC285 -> 1.5808057 | J27: ='[1]ÜDM sahələr üzrə'!AD285 -> 3.2958687 | K27: ='[1]ÜDM sahələr üzrə'!AE285 -> 6.4155876 | L27: ='[1]ÜDM sahələr üzrə'!AF285 -> 6.217238 | M27: ='[1]ÜDM sahələr üzrə'!AG285 -> 11.56449 | N27: ='[1]ÜDM sahələr üzrə'!AH285 -> 10.68429 | O27: ='[1]ÜDM sahələr üzrə'!AI285 -> 2.6086468 | P27: ='[1]ÜDM sahələr üzrə'!AJ285 -> 2.4894437 | ... U27: ='[1]ÜDM sahələr üzrə'!AO285 -> 6.8473652
A28: 4.1 | B28: Ticarət, nəqliyyat vasitələrinin təmiri | C28: ÜDM-də payı, % | D28: 7.1308996 | E28: 7.8828619 | F28: 9.9077049 | G28: 10.346346 | H28: 10.364864 | I28: =I29/'2.4.1.1.'!I$4*100 -> 9.5728662 | J28: =J29/'2.4.1.1.'!J$4*100 -> 9.9954577 | K28: =K29/'2.4.1.1.'!K$4*100 -> 11.527582 | L28: =L29/'2.4.1.1.'!L$4*100 -> 10.021523 | M28: =M29/'2.4.1.1.'!M$4*100 -> 8.1750252 | N28: =N29/'2.4.1.1.'!N$4*100 -> 10.433415 | O28: =O29/'2.4.1.1.'!O$4*100 -> 10.695678 | P28: =P29/'2.4.1.1.'!P$4*100 -> 11.239755 | ... U28: =U29/'2.4.1.1.'!U$4*100 -> 14.126831
B29: əlavə dəyər | C29: mln AZN | D29: 4148.9 | E29: 4652 | F29: 5387.8 | G29: 6251.8 | H29: 7290.42 | I29: ='[1]ÜDM sahələr üzrə'!AC289 -> 7667.1 | J29: ='[1]ÜDM sahələr üzrə'!AD289 -> 8185.9 | K29: ='[1]ÜDM sahələr üzrə'!AE289 -> 8366.5 | L29: ='[1]ÜDM sahələr üzrə'!AF289 -> 9340.38 | M29: ='[1]ÜDM sahələr üzrə'!AG289 -> 10952.3 | N29: ='[1]ÜDM sahələr üzrə'!AH289 -> 12846.5 | O29: ='[1]ÜDM sahələr üzrə'!AI289 -> 13512.6 | P29: ='[1]ÜDM sahələr üzrə'!AJ289 -> 14401.972 | ... U29: ='[1]ÜDM sahələr üzrə'!AO289 -> 23788.587
B30: real artım tempi | C30: % | D30: 9.85 | E30: 10 | F30: 10.9 | G30: 1.5 | H30: 2.516 | I30: ='[1]ÜDM sahələr üzrə'!AC291 -> 3 | J30: ='[1]ÜDM sahələr üzrə'!AD291 -> 3.6 | K30: ='[1]ÜDM sahələr üzrə'!AE291 -> -1.3 | L30: ='[1]ÜDM sahələr üzrə'!AF291 -> 4.9 | M30: ='[1]ÜDM sahələr üzrə'!AG291 -> 3.24 | N30: ='[1]ÜDM sahələr üzrə'!AH291 -> 3.5 | O30: ='[1]ÜDM sahələr üzrə'!AI291 -> 3.8 | P30: ='[1]ÜDM sahələr üzrə'!AJ291 -> 4.7566523 | ... U30: ='[1]ÜDM sahələr üzrə'!AO291 -> 3.9111247
B31: deflyator | C31: % | D31: 3.3628232 | E31: 1.9328234 | F31: 4.4335915 | G31: 14.321409 | H31: 13.751156 | I31: ='[1]ÜDM sahələr üzrə'!AC294 -> 2.1039505 | J31: ='[1]ÜDM sahələr üzrə'!AD294 -> 3.0565387 | K31: ='[1]ÜDM sahələr üzrə'!AE294 -> 3.5524141 | L31: ='[1]ÜDM sahələr üzrə'!AF294 -> 6.4253879 | M31: ='[1]ÜDM sahələr üzrə'!AG294 -> 13.577627 | N31: ='[1]ÜDM sahələr üzrə'!AH294 -> 13.3285 | O31: ='[1]ÜDM sahələr üzrə'!AI294 -> 1.334364 | P31: ='[1]ÜDM sahələr üzrə'!AJ294 -> 1.7422721 | ... U31: ='[1]ÜDM sahələr üzrə'!AO294 -> 7.2035648
A32: 4.2 | B32: Turistlərin yerləşdirilməsi və ictimai iaşə | C32: ÜDM-də payı, % | D32: 1.8376818 | E32: 2.150503 | F32: 2.4141273 | G32: 2.3567982 | H32: 2.3668915 | I32: =I33/'2.4.1.1.'!I$4*100 -> 2.2901164 | J32: =J33/'2.4.1.1.'!J$4*100 -> 2.4179388 | K32: =K33/'2.4.1.1.'!K$4*100 -> 1.1424934 | L32: =L33/'2.4.1.1.'!L$4*100 -> 1.2620597 | M32: =M33/'2.4.1.1.'!M$4*100 -> 1.5198622 | N32: =N33/'2.4.1.1.'!N$4*100 -> 2.1729343 | O32: =O33/'2.4.1.1.'!O$4*100 -> 2.4444935 | P32: =P33/'2.4.1.1.'!P$4*100 -> 2.631195 | ... U32: =U33/'2.4.1.1.'!U$4*100 -> 2.152894
B33: əlavə dəyər | C33: mln AZN | D33: 1069.2 | E33: 1269.1 | F33: 1312.8 | G33: 1424.1 | H33: 1664.82 | I33: ='[1]ÜDM sahələr üzrə'!AC300 -> 1834.2 | J33: ='[1]ÜDM sahələr üzrə'!AD300 -> 1980.2 | K33: ='[1]ÜDM sahələr üzrə'!AE300 -> 829.2 | L33: ='[1]ÜDM sahələr üzrə'!AF300 -> 1176.28 | M33: ='[1]ÜDM sahələr üzrə'!AG300 -> 2036.2 | N33: ='[1]ÜDM sahələr üzrə'!AH300 -> 2675.5 | O33: ='[1]ÜDM sahələr üzrə'!AI300 -> 3088.3 | P33: ='[1]ÜDM sahələr üzrə'!AJ300 -> 3371.461 | ... U33: ='[1]ÜDM sahələr üzrə'!AO300 -> 3625.3216
B34: real artım tempi | C34: % | D34: 16 | E34: 18.2 | F34: 14 | G34: 2.1 | H34: 6.9 | I34: ='[1]ÜDM sahələr üzrə'!AC302 -> 7.6 | J34: ='[1]ÜDM sahələr üzrə'!AD302 -> 6.4 | K34: ='[1]ÜDM sahələr üzrə'!AE302 -> -58.93 | L34: ='[1]ÜDM sahələr üzrə'!AF302 -> 34.02 | M34: ='[1]ÜDM sahələr üzrə'!AG302 -> 50.3 | N34: ='[1]ÜDM sahələr üzrə'!AH302 -> 21.5 | O34: ='[1]ÜDM sahələr üzrə'!AI302 -> 12.9 | P34: ='[1]ÜDM sahələr üzrə'!AJ302 -> 10.216421 | ... U34: ='[1]ÜDM sahələr üzrə'!AO302 -> 6.5797348
B35: deflyator | C35: % | D35: 2.7105124 | E35: 0.41981512 | F35: -9.2601885 | G35: 6.2468777 | H35: 9.3576308 | I35: ='[1]ÜDM sahələr üzrə'!AC305 -> 2.3934911 | J35: ='[1]ÜDM sahələr üzrə'!AD305 -> 1.4660465 | K35: ='[1]ÜDM sahələr üzrə'!AE305 -> 1.9589923 | L35: ='[1]ÜDM sahələr üzrə'!AF305 -> 5.8477927 | M35: ='[1]ÜDM sahələr üzrə'!AG305 -> 15.173016 | N35: ='[1]ÜDM sahələr üzrə'!AH305 -> 8.145448 | O35: ='[1]ÜDM sahələr üzrə'!AI305 -> 2.2399396 | P35: ='[1]ÜDM sahələr üzrə'!AJ305 -> -0.95048592 | ... U35: ='[1]ÜDM sahələr üzrə'!AO305 -> 7.0659167
A36: 4.3 | B36: Nəqliyyat və anbar təsərrüfatı | C36: ÜDM-də payı, % | D36: 4.4152831 | E36: 4.5004499 | F36: 5.9615777 | G36: 6.7450335 | H36: 6.7085098 | I36: =I37/'2.4.1.1.'!I$4*100 -> 6.1527993 | J36: =J37/'2.4.1.1.'!J$4*100 -> 5.9430108 | K36: =K37/'2.4.1.1.'!K$4*100 -> 7.1295611 | L36: =L37/'2.4.1.1.'!L$4*100 -> 6.855977 | M36: =M37/'2.4.1.1.'!M$4*100 -> 6.0623108 | N36: =N37/'2.4.1.1.'!N$4*100 -> 6.3567771 | O36: =O37/'2.4.1.1.'!O$4*100 -> 6.9836226 | P36: =P37/'2.4.1.1.'!P$4*100 -> 7.308644 | ... U36: =U37/'2.4.1.1.'!U$4*100 -> 9.0091781
B37: əlavə dəyər | C37: mln AZN | D37: 2568.9 | E37: 2655.9 | F37: 3241.9 | G37: 4075.7 | H37: 4718.62 | I37: ='[1]ÜDM sahələr üzrə'!AC311 -> 4927.9 | J37: ='[1]ÜDM sahələr üzrə'!AD311 -> 4867.1 | K37: ='[1]ÜDM sahələr üzrə'!AE311 -> 5174.5 | L37: ='[1]ÜDM sahələr üzrə'!AF311 -> 6389.99 | M37: ='[1]ÜDM sahələr üzrə'!AG311 -> 8121.84 | N37: ='[1]ÜDM sahələr üzrə'!AH311 -> 7827 | O37: ='[1]ÜDM sahələr üzrə'!AI311 -> 8822.9 | P37: ='[1]ÜDM sahələr üzrə'!AJ311 -> 9364.8735 | ... U37: ='[1]ÜDM sahələr üzrə'!AO311 -> 15170.82
B38: real artım tempi | C38: % | D38: 6.25 | E38: 4.7 | F38: -1 | G38: -0.7 | H38: 8.5 | I38: ='[1]ÜDM sahələr üzrə'!AC313 -> 7.7 | J38: ='[1]ÜDM sahələr üzrə'!AD313 -> 1.25 | K38: ='[1]ÜDM sahələr üzrə'!AE313 -> 4.89 | L38: ='[1]ÜDM sahələr üzrə'!AF313 -> 16.4 | M38: ='[1]ÜDM sahələr üzrə'!AG313 -> 24.78 | N38: ='[1]ÜDM sahələr üzrə'!AH313 -> -7 | O38: ='[1]ÜDM sahələr üzrə'!AI313 -> 14.1 | P38: ='[1]ÜDM sahələr üzrə'!AJ313 -> 7.8006887 | ... U38: ='[1]ÜDM sahələr üzrə'!AO313 -> 0.55273522
B39: deflyator | C39: % | D39: -10.239522 | E39: -1.2543806 | F39: 9.8 | G39: 26.605726 | H39: 6.704579 | I39: ='[1]ÜDM sahələr üzrə'!AC314 -> -3.0309771 | J39: ='[1]ÜDM sahələr üzrə'!AD314 -> -2.4531272 | K39: ='[1]ÜDM sahələr üzrə'!AE314 -> 1.3594013 | L39: ='[1]ÜDM sahələr üzrə'!AF314 -> 6.0910645 | M39: ='[1]ÜDM sahələr üzrə'!AG314 -> 1.861313 | N39: ='[1]ÜDM sahələr üzrə'!AH314 -> 3.6234281 | O39: ='[1]ÜDM sahələr üzrə'!AI314 -> -1.2060434 | P39: ='[1]ÜDM sahələr üzrə'!AJ314 -> -1.5379163 | ... U39: ='[1]ÜDM sahələr üzrə'!AO314 -> 9.4134077
A40: 4.4 | B40: İnformasiya və rabitə | C40: ÜDM-də payı, % | D40: 1.7391977 | E40: 1.8146511 | F40: 2.0000037 | G40: 1.7510906 | H40: 1.6264364 | I40: =I41/'2.4.1.1.'!I$4*100 -> 1.5673226 | J40: =J41/'2.4.1.1.'!J$4*100 -> 1.7976414 | K40: =K41/'2.4.1.1.'!K$4*100 -> 2.120061 | L40: =L41/'2.4.1.1.'!L$4*100 -> 1.763963 | M40: =M41/'2.4.1.1.'!M$4*100 -> 1.3807442 | N40: =N41/'2.4.1.1.'!N$4*100 -> 1.7440326 | O40: =O41/'2.4.1.1.'!O$4*100 -> 1.8992851 | P40: =P41/'2.4.1.1.'!P$4*100 -> 2.0691445 | ... U40: =U41/'2.4.1.1.'!U$4*100 -> 2.5460893
...

Sheet 2.4.1.4.
A1: Azərbaycan Respublikasında istehsal olunan əsas məhsul növlərinin sahələr üzrə natural göstəricilərinin proqnozu (o cümlədən aksizli məhsulların növləri üzrə)
A2: № | B2: Göstəricilər | C2: Ölçü vahidi | D2: Hesabat | P2: Proqnoz
D3: =E3-1 -> 2013 | E3: =F3-1 -> 2014 | F3: =G3-1 -> 2015 | G3: =H3-1 -> 2016 | H3: =I3-1 -> 2017 | I3: =J3-1 -> 2018 | J3: =K3-1 -> 2019 | K3: =L3-1 -> 2020 | L3: =M3-1 -> 2021 | M3: 2022 | N3: 2023 | O3: 2024 | P3: 2025 | Q3: 2026 | R3: 2027 | S3: 2028 | T3: 2029 | U3: 2030
A4: 1. | B4: Kənd, meşə və balıqçılıq təsərrüfatı
A5: 1.1 | B5: Bitkiçilik sahəsi
B6: Dənli və dənli paxlalılar | C6: min ton | D6: 2955.3 | E6: 2383.3 | F6: 2999.4 | G6: 3065.1 | H6: 2928.8 | I6: ='[3]4_'!AC8 -> 3309.2 | J6: ='[3]4_'!AD8 -> 3538.46 | K6: ='[3]4_'!AE8 -> 3257.1 | L6: ='[3]4_'!AF8 -> 3363 | M6: ='[3]4_'!AG8 -> 3161.3 | N6: ='[3]4_'!AH8 -> 3248.59 | O6: ='[3]4_'!AI8 -> 3278.1 | P6: ='[3]4_'!AJ8 -> 3224.9894 | ... U6: ='[3]4_'!AO8 -> 3448.11
B7: o cümlədən, buğda | C7: min ton | D7: 1893.4 | E7: 1449.1 | F7: 1687.7 | G7: 1851.4 | H7: 1818.7 | I7: ='[3]4_'!AC9 -> 2042.9 | J7: ='[3]4_'!AD9 -> 2171.5 | K7: ='[3]4_'!AE9 -> 1867.3 | L7: ='[3]4_'!AF9 -> 1885.4 | M7: ='[3]4_'!AG9 -> 1736.1 | N7: ='[3]4_'!AH9 -> 1833.9 | O7: ='[3]4_'!AI9 -> 1685.7 | P7: ='[3]4_'!AJ9 -> 1579.0245 | ... U7: ='[3]4_'!AO9 -> 1684.8
B8: o cümlədən, çəltik | C8: min ton | D8: 4.9 | E8: 2.8 | F8: 3 | G8: 5.6 | H8: 16.2 | I8: ='[3]4_'!AC10 -> 12.4 | J8: ='[3]4_'!AD10 -> 11.96 | K8: ='[3]4_'!AE10 -> 9.9 | L8: ='[3]4_'!AF10 -> 10.7 | M8: ='[3]4_'!AG10 -> 11.6 | N8: ='[3]4_'!AH10 -> 14.9 | O8: ='[3]4_'!AI10 -> 19.6 | P8: ='[3]4_'!AJ10 -> 19.36192 | ... U8: ='[3]4_'!AO10 -> 20.96
B9: Tərəvəz | C9: min ton | D9: 1236.3 | E9: 1187.7 | F9: 1275.3 | G9: 1270.6 | H9: 1405.6 | I9: ='[3]4_'!AC11 -> 1521.9 | J9: ='[3]4_'!AD11 -> 1714.7 | K9: ='[3]4_'!AE11 -> 1738.9 | L9: ='[3]4_'!AF11 -> 1815.5 | M9: ='[3]4_'!AG11 -> 1823.3 | N9: ='[3]4_'!AH11 -> 1825.6 | O9: ='[3]4_'!AI11 -> 1838.9 | P9: ='[3]4_'!AJ11 -> 1856.278 | ... U9: ='[3]4_'!AO11 -> 2022.5
B10: Bostan | C10: min ton | D10: 429.8 | E10: 440.9 | F10: 484.5 | G10: 464.6 | H10: 438.1 | I10: ='[3]4_'!AC12 -> 401.9 | J10: ='[3]4_'!AD12 -> 447.6 | K10: ='[3]4_'!AE12 -> 448.1 | L10: ='[3]4_'!AF12 -> 459.9 | M10: ='[3]4_'!AG12 -> 469.3 | N10: ='[3]4_'!AH12 -> 438.2 | O10: ='[3]4_'!AI12 -> 490.6 | P10: ='[3]4_'!AJ12 -> 474.0012 | ... U10: ='[3]4_'!AO12 -> 539.72
B11: Kartof | C11: min ton | D11: 992.8 | E11: 819.3 | F11: 839.8 | G11: 902.4 | H11: 913.9 | I11: ='[3]4_'!AC13 -> 898.9 | J11: ='[3]4_'!AD13 -> 1004.2 | K11: ='[3]4_'!AE13 -> 1037.6 | L11: ='[3]4_'!AF13 -> 1062 | M11: ='[3]4_'!AG13 -> 1074.3 | N11: ='[3]4_'!AH13 -> 1010.5 | O11: ='[3]4_'!AI13 -> 927.4 | P11: ='[3]4_'!AJ13 -> 946.76232 | ... U11: ='[3]4_'!AO13 -> 1142.2
B12: Pambıq | C12: min ton | D12: 45.2 | E12: 41 | F12: 35.2 | G12: 89.4 | H12: 207.5 | I12: ='[3]4_'!AC14 -> 233.6 | J12: ='[3]4_'!AD14 -> 295.295 | K12: ='[3]4_'!AE14 -> 336.8 | L12: ='[3]4_'!AF14 -> 287 | M12: ='[3]4_'!AG14 -> 322.5 | N12: ='[3]4_'!AH14 -> 276.3 | O12: ='[3]4_'!AI14 -> 310.8 | P12: ='[3]4_'!AJ14 -> 305.78184 | ... U12: ='[3]4_'!AO14 -> 316.725
B13: Tütün | C13: min ton | D13: 3.5 | E13: 2.9 | F13: 3.5 | G13: 3.6 | H13: 5.3 | I13: ='[3]4_'!AC15 -> 6.3 | J13: ='[3]4_'!AD15 -> 6 | K13: ='[3]4_'!AE15 -> 6.9 | L13: ='[3]4_'!AF15 -> 6.4 | M13: ='[3]4_'!AG15 -> 5.1 | N13: ='[3]4_'!AH15 -> 6.3 | O13: ='[3]4_'!AI15 -> 6.5 | P13: ='[3]4_'!AJ15 -> 7.5215 | ... U13: ='[3]4_'!AO15 -> 6.7375
B14: Şəkər çuğunduru | C14: min ton | D14: 187.9 | E14: 173.3 | F14: 184.3 | G14: 345.8 | H14: 435 | I14: ='[3]4_'!AC16 -> 299.4 | J14: ='[3]4_'!AD16 -> 237 | K14: ='[3]4_'!AE16 -> 253.3 | L14: ='[3]4_'!AF16 -> 193.2 | M14: ='[3]4_'!AG16 -> 222.7 | N14: ='[3]4_'!AH16 -> 219.8 | O14: ='[3]4_'!AI16 -> 290.1 | P14: ='[3]4_'!AJ16 -> 318.62748 | ... U14: ='[3]4_'!AO16 -> 318.24
B15: Dən üçün günəbaxan | C15: min ton | D15: 17.7 | E15: 19.8 | F15: 18.4 | G15: 17.1 | H15: 30.6 | I15: ='[3]4_'!AC17 -> 24.3 | J15: ='[3]4_'!AD17 -> 34.8 | K15: ='[3]4_'!AE17 -> 24.8 | L15: ='[3]4_'!AF17 -> 25.8 | M15: ='[3]4_'!AG17 -> 29.4 | N15: ='[3]4_'!AH17 -> 29.3 | O15: ='[3]4_'!AI17 -> 31.2 | P15: ='[3]4_'!AJ17 -> 31.30386 | ... U15: ='[3]4_'!AO17 -> 33.7
B16: Meyvə və giləmeyvə | C16: min ton | D16: 853.8 | E16: 850.8 | F16: 888.4 | G16: 882.8 | H16: 954.8 | I16: ='[3]4_'!AC18 -> 1010.8 | J16: ='[3]4_'!AD18 -> 1099.7 | K16: ='[3]4_'!AE18 -> 1133.1 | L16: ='[3]4_'!AF18 -> 1204.9 | M16: ='[3]4_'!AG18 -> 1253.1 | N16: ='[3]4_'!AH18 -> 1261.3 | O16: ='[3]4_'!AI18 -> 1317.9 | P16: ='[3]4_'!AJ18 -> 1392.2765 | ... U16: ='[3]4_'!AO18 -> 1516.08
B17: Üzüm | C17: min ton | D17: 148.5 | E17: 147.7 | F17: 157.1 | G17: 136.5 | H17: 152.8 | I17: ='[3]4_'!AC19 -> 167.6 | J17: ='[3]4_'!AD19 -> 201.8423 | K17: ='[3]4_'!AE19 -> 208 | L17: ='[3]4_'!AF19 -> 209.8 | M17: ='[3]4_'!AG19 -> 212.6 | N17: ='[3]4_'!AH19 -> 224.5 | O17: ='[3]4_'!AI19 -> 205.1 | P17: ='[3]4_'!AJ19 -> 205.6 | ... U17: ='[3]4_'!AO19 -> 216.98
B18: Çay yarpağı | C18: min ton | D18: 0.57 | E18: 0.47 | F18: 0.58 | G18: 1.02 | H18: 0.78 | I18: ='[3]4_'!AC20 -> 0.87 | J18: ='[3]4_'!AD20 -> 0.9294 | K18: ='[3]4_'!AE20 -> 0.9315 | L18: ='[3]4_'!AF20 -> 1.1777 | M18: ='[3]4_'!AG20 -> 1.0009 | N18: ='[3]4_'!AH20 -> 1.1238 | O18: ='[3]4_'!AI20 -> 1.0695 | P18: ='[3]4_'!AJ20 -> 1.0875 | ... U18: ='[3]4_'!AO20 -> 1.26
A19: 1.2 | B19: Heyvandarlıq sahəsi
B20: Ət (diri çəkidə) | C20: min ton | D20: 286.9 | E20: 291.2 | F20: 298.6 | G20: 302.2 | H20: 316.8 | I20: ='[3]4_'!AC22 -> 556.6 | J20: ='[3]4_'!AD22 -> 573.3 | K20: ='[3]4_'!AE22 -> 591.1 | L20: ='[3]4_'!AF22 -> 610 | M20: ='[3]4_'!AG22 -> 628.0291 | N20: ='[3]4_'!AH22 -> 647.7492 | O20: ='[3]4_'!AI22 -> 659 | P20: ='[3]4_'!AJ22 -> 672.51975 | ... U20: ='[3]4_'!AO22 -> 741.82087
B21: o cümlədən mal əti | C21: min ton | D21: 120.8 | E21: 122.4 | F21: 129.8 | G21: 131 | H21: 132.9 | I21: ='[3]4_'!AC23 -> 239.9 | J21: ='[3]4_'!AD23 -> 243.7 | K21: ='[3]4_'!AE23 -> 252.8787 | L21: ='[3]4_'!AF23 -> 256.6 | M21: ='[3]4_'!AG23 -> 263.0966 | N21: ='[3]4_'!AH23 -> 271.6358 | O21: ='[3]4_'!AI23 -> 272 | P21: ='[3]4_'!AJ23 -> 275.264 | ... U21: ='[3]4_'!AO23 -> 297.72438
B22: o cümlədən qoyun əti | C22: min ton | D22: 70.9 | E22: 68.7 | F22: 70.9 | G22: 75.2 | H22: 79.1 | I22: ='[3]4_'!AC24 -> 165.7 | J22: ='[3]4_'!AD24 -> 174.7 | K22: ='[3]4_'!AE24 -> 178.4168 | L22: ='[3]4_'!AF24 -> 180 | M22: ='[3]4_'!AG24 -> 183.673 | N22: ='[3]4_'!AH24 -> 184.0101 | O22: ='[3]4_'!AI24 -> 185.9 | P22: ='[3]4_'!AJ24 -> 186.6728 | ... U22: ='[3]4_'!AO24 -> 195.913
B23: o cümlədən quş əti | C23: min ton | D23: 94.5 | E23: 99.4 | F23: 97.2 | G23: 95.5 | H23: 104.3 | I23: ='[3]4_'!AC25 -> 150.3 | J23: ='[3]4_'!AD25 -> 154.2 | K23: ='[3]4_'!AE25 -> 159.1381 | L23: ='[3]4_'!AF25 -> 172.7 | M23: ='[3]4_'!AG25 -> 180.5469 | N23: ='[3]4_'!AH25 -> 191.4049 | O23: ='[3]4_'!AI25 -> 200.4 | P23: ='[3]4_'!AJ25 -> 209.87077 | ... U23: ='[3]4_'!AO25 -> 247.35033
B24: Yumurta | C24: mln ədəd | D24: 1401.5 | E24: 1562.7 | F24: 1552.9 | G24: 1609.8 | H24: 1714 | I24: ='[3]4_'!AC26 -> 1676.2 | J24: ='[3]4_'!AD26 -> 1827.1 | K24: ='[3]4_'!AE26 -> 1906.2 | L24: ='[3]4_'!AF26 -> 1838.8 | M24: ='[3]4_'!AG26 -> 2018.146 | N24: ='[3]4_'!AH26 -> 2188.2 | O24: ='[3]4_'!AI26 -> 2300.8 | P24: ='[3]4_'!AJ26 -> 2400 | ... U24: ='[3]4_'!AO26 -> 2728.3341
B25: Süd (fiziki çəkidə) | C25: min ton | D25: 1796.7 | E25: 1855.8 | F25: 1924.5 | G25: 2009.9 | H25: 2024.1 | I25: ='[3]4_'!AC27 -> 2080.4 | J25: ='[3]4_'!AD27 -> 2150.8 | K25: ='[3]4_'!AE27 -> 2192.5 | L25: ='[3]4_'!AF27 -> 2223.4 | M25: ='[3]4_'!AG27 -> 2264.678 | N25: ='[3]4_'!AH27 -> 2284 | O25: ='[3]4_'!AI27 -> 2298.5 | P25: ='[3]4_'!AJ27 -> 2321.4 | ... U25: ='[3]4_'!AO27 -> 2500.5105
B26: Yun (fiziki çəkidə) | C26: min ton | D26: 16.5 | E26: 16.8 | F26: 17 | G26: 16.7 | H26: 16 | I26: ='[3]4_'!AC28 -> 15.8 | J26: ='[3]4_'!AD28 -> 16.0986 | K26: ='[3]4_'!AE28 -> 16.1 | L26: ='[3]4_'!AF28 -> 16.1 | M26: ='[3]4_'!AG28 -> 15.772 | N26: ='[3]4_'!AH28 -> 15.1 | O26: ='[3]4_'!AI28 -> 14.8 | P26: ='[3]4_'!AJ28 -> 15.038293 | ... U26: ='[3]4_'!AO28 -> 15.721492
B27: Barama (yaş çəkidə) | C27: ton | D27: 0.0014 | E27: 0.000974 | F27: 0.000236 | G27: 70.7 | H27: 245.2 | I27: ='[3]4_'!AC29 -> 513.9 | J27: ='[3]4_'!AD29 -> 643.7 | K27: ='[3]4_'!AE29 -> 446.6 | L27: ='[3]4_'!AF29 -> 497.4 | M27: ='[3]4_'!AG29 -> 341.4 | N27: ='[3]4_'!AH29 -> 357 | O27: ='[3]4_'!AI29 -> 239.4 | P27: ='[3]4_'!AJ29 -> 250 | ... U27: ='[3]4_'!AO29 -> 280
B28: İri buynuzlu mal-qara | C28: min baş | D28: 2703.3 | E28: 2697.5 | F28: 2708.3 | G28: 2698.5 | H28: 2673 | I28: ='[3]4_'!AC30 -> 2658.8 | J28: ='[3]4_'!AD30 -> 2646.6 | K28: ='[3]4_'!AE30 -> 2650.7 | L28: ='[3]4_'!AF30 -> 2648.8 | M28: ='[3]4_'!AG30 -> 2618.1 | N28: ='[3]4_'!AH30 -> 2507.7 | O28: ='[3]4_'!AI30 -> 2465.622 | P28: ='[3]4_'!AJ30 -> 2482.3 | ... U28: ='[3]4_'!AO30 -> 2537.9282
B29: İnək-camış | C29: min baş | D29: 1301.6 | E29: 1299.2 | F29: 1303 | G29: 1299 | H29: 1285.8 | I29: ='[3]4_'!AC31 -> 1279.1 | J29: ='[3]4_'!AD31 -> 1278.2 | K29: ='[3]4_'!AE31 -> 1280.5 | L29: ='[3]4_'!AF31 -> 1288 | M29: ='[3]4_'!AG31 -> 1288.8 | N29: ='[3]4_'!AH31 -> 1235.1 | O29: ='[3]4_'!AI31 -> 1224.201 | P29: ='[3]4_'!AJ31 -> 1232.605 | ... U29: ='[3]4_'!AO31 -> 1250.1269
B30: Qoyun və keçilər | C30: min baş | D30: 8630.5 | E30: 8645.4 | F30: 8677.1 | G30: 8614.8 | H30: 8454.3 | I30: ='[3]4_'!AC32 -> 8304.1 | J30: ='[3]4_'!AD32 -> 8189.2 | K30: ='[3]4_'!AE32 -> 8089.65 | L30: ='[3]4_'!AF32 -> 7899.7 | M30: ='[3]4_'!AG32 -> 7751.7 | N30: ='[3]4_'!AH32 -> 7060.6 | O30: ='[3]4_'!AI32 -> 6896.52 | P30: ='[3]4_'!AJ32 -> 6904 | ... U30: ='[3]4_'!AO32 -> 6931.0716
B31: Donuzlar | C31: min baş | D31: 6.7 | E31: 6.1 | F31: 5.2 | G31: 4.4 | H31: 4.9 | I31: ='[3]4_'!AC33 -> 5.5 | J31: ='[3]4_'!AD33 -> 5.7 | K31: ='[3]4_'!AE33 -> 5.9 | L31: ='[3]4_'!AF33 -> 6 | M31: ='[3]4_'!AG33 -> 5.1 | N31: ='[3]4_'!AH33 -> 4.8 | O31: ='[3]4_'!AI33 -> 3.1 | P31: ='[3]4_'!AJ33 -> 3.1138605 | ... U31: ='[3]4_'!AO33 -> 3.6602897
B32: Quş | C32: mln baş | D32: 25.1727 | E32: 28.8517 | F32: 27.5594 | G32: 28.0095 | H32: 30.4734 | I32: ='[3]4_'!AC34 -> 30.4984 | J32: ='[3]4_'!AD34 -> 32.2302 | K32: ='[3]4_'!AE34 -> 30.175812 | L32: ='[3]4_'!AF34 -> 29.6 | M32: ='[3]4_'!AG34 -> 29.7949 | N32: ='[3]4_'!AH34 -> 28.6983 | O32: ='[3]4_'!AI34 -> 29.3 | P32: ='[3]4_'!AJ34 -> 29.38 | ... U32: ='[3]4_'!AO34 -> 29.6
A33: 2. | B33: Mədənçıxarma sənayesi
A34: 2.1. | B34: Xam neft və təbii qaz hasilatı
B35: Neft hasilatı | C35: min ton | D35: 43016.643 | E35: 42056.057 | F35: 41644.02 | G35: 41205.102 | H35: 38755.992 | I35: ='[4]O&G'!AC6 -> 38814.28 | J35: ='[4]O&G'!AD6 -> 37453.7 | K35: ='[4]O&G'!AE6 -> 34532.02 | L35: ='[4]O&G'!AF6 -> 34580.32 | M35: ='[4]O&G'!AG6 -> 32646.4 | N35: ='[4]O&G'!AH6 -> 30147.4 | O35: ='[4]O&G'!AI6 -> 29052.201 | P35: ='[4]O&G'!AJ6 -> 28453.311 | ... U35: ='[4]O&G'!AO6 -> 27282.868
B36: Qaz hasilatı | C36: mln m3 | D36: 29420.1 | E36: 29500.086 | F36: 29175.1 | G36: 29331.4 | H36: 28597.9 | I36: ='[4]O&G'!AC29 -> 30490.32 | J36: ='[4]O&G'!AD29 -> 35616.51 | K36: ='[4]O&G'!AE29 -> 37140.9 | L36: ='[4]O&G'!AF29 -> 43867.39 | M36: ='[4]O&G'!AG29 -> 46737.1 | N36: ='[4]O&G'!AH29 -> 48497.2 | O36: ='[4]O&G'!AI29 -> 50339.395 | P36: ='[4]O&G'!AJ29 -> 50386.595 | ... U36: ='[4]O&G'!AO29 -> 48054.081
